Workbook

Sheet 🏠 หน้าหลัก
A1: 🏠 DA-YO — หน้าหลัก
A2: คลิกชื่อชีตสีฟ้าเพื่อกระโดดไปหน้านั้น · แท็บด้านล่างแบ่งสีตามหมวด · ชีตเบื้องหลังถูกซ่อนไว้ (วิธีเปิดดูท้ายหน้า)
B4: 📊 ภาพรวม | F4: 📦 สต็อก & บันทึกประจำวัน
B5: Dashboard | C5: ยอดขาย กำไร มูลค่าสต็อก ตามช่วงวันที่ | F5: สินค้าและสต็อก | G5: ⭐ ทะเบียนสินค้า + สต็อกคงเหลืออัตโนมัติ
F6: บันทึกซื้อ | G6: ลงบิลซื้อวัตถุดิบ/บรรจุภัณฑ์
B7: 🍵 เมนู & สูตร — ชาไทย / ชาเขียว | F7: บันทึกขาย | G7: ลงการขายทีละแก้ว → ตัดสต็อกเอง
B8: คำนวณสูตร | C8: เลือกเมนู+ขนาด+หวาน → ได้สูตร ต้นทุน GP | F8: ปรับสต็อก | G8: ยอดยกมา ของเสีย นับจริงไม่ตรง
B9: ข้อมูลสูตร | C9: ⭐ ต้นทางสูตรทั้งหมด 360 แถว — แก้ปริมาณที่นี่ | F9: ทะเบียนอุปกรณ์ | G9: อุปกรณ์ในร้าน + ค่าเสื่อม
B10: ต้นทุนและราคา | C10: ต้นทุนต่อหน่วย + ตารางราคาขาย 3 ขนาด
B11: SOP วิธีชง | C11: ขั้นตอนชงหน้าร้าน
F12: 👅 การชิม / R&D
F13: R&D Log | G13: บันทึกผลชิมแต่ละรอบ (JAR 1–5)
F14: สรุปการชิม | G14: สรุปว่าเมนูไหนต้องปรับหวาน/เข้มชา
B15: 🧪 การทำเบส
B16: เตรียมเบส | C16: กรอกยอดคาดขาย → บอกว่าต้องทำเบสกี่ batch
B17: เบสและซับสูตร | C17: สูตรเบสแต่ละตัว ปรับตามปริมาณที่จะทำ | F17: ✨ มัทฉะพรีเมียม
B18: ต้นทุนเบส | C18: ⭐ BOM: เบสแต่ละตัวใช้สินค้าอะไร เท่าไหร่ | F18: มัทฉะพรีเมียม | G18: ต้นทุนผงมัทฉะ ตารางความไว เกรดผง
B21: 🗂 ชีตเบื้องหลัง (ซ่อนไว้)
B22: ตารางรวม | C22: เครื่องมิเรอร์สูตร 360 แถว — ห้ามแก้ ระบบใช้ค้นหา
B23: Lists | C23: รายการแม่ของ dropdown ทุกตัว (เมนู ขนาด หมวดย่อย)
B24: Schema | C24: คู่มือว่าคอลัมน์ไหนกรอกได้/เป็นสูตร
B25: เคล็ดลับ | C25: โน้ตเทคนิคหน้าร้าน
B26: สรุปการแก้ไข | C26: ประวัติการแก้ไฟล์
B28: วิธีเปิดชีตที่ซ่อน: คลิกขวาที่แท็บใดก็ได้ด้านล่าง → Unhide → เลือกชื่อชีต → OK
B29: ชีตทั้งหมดเรียงตามหมวดในแท็บด้านล่างแล้ว — กลับมาหน้านี้ได้จากแท็บ 🏠 หน้าหลัก ซ้ายสุด

Sheet Dashboard
A1: 📈 Dashboard — ภาพรวมยอดขาย กำไร และสต็อก
A2: เปลี่ยนช่วงวันที่ในช่องครีม (B4 / D4) ตัวเลขทั้งหน้าจะคำนวณใหม่ · ค่าเริ่มต้น = ต้นเดือนนี้ถึงวันนี้
A4: ช่วงวันที่: จาก | B4: =DATE(YEAR(TODAY()),MONTH(TODAY()),1) -> 46266 | C4: ถึง | D4: =TODAY() -> 46282
A6: ยอดขายในช่วงที่เลือก
A7: จำนวนแก้ว | B7: ยอดขาย (บาท) | C7: ต้นทุนวัตถุดิบ (บาท) | D7: กำไรขั้นต้น (บาท) | E7: GP % | F7: จำนวนรายการขาย
A8: =SUMIFS(tblSales[จำนวนแก้ว],tblSales[วันที่],">="&$B$4,tblSales[วันที่],"<="&$D$4) -> 0 | B8: =SUMIFS(tblSales[ยอดขาย (บาท)],tblSales[วันที่],">="&$B$4,tblSales[วันที่],"<="&$D$4) -> 0 | C8: =SUMIFS(tblSales[ต้นทุนรวม (บาท)],tblSales[วันที่],">="&$B$4,tblSales[วันที่],"<="&$D$4) -> 0 | D8: =SUMIFS(tblSales[กำไร (บาท)],tblSales[วันที่],">="&$B$4,tblSales[วันที่],"<="&$D$4) -> 0 | E8: =IFERROR(D8/B8,0) -> 0 | F8: =COUNTIFS(tblSales[วันที่],">="&$B$4,tblSales[วันที่],"<="&$D$4) -> 0
A10: สถานะสต็อกและทรัพย์สิน (ณ ปัจจุบัน)
A11: มูลค่าสต็อกคงเหลือ (บาท) | B11: สินค้าใกล้หมด (รายการ) | C11: สินค้าหมด (รายการ) | D11: ยอดซื้อในช่วงที่เลือก (บาท) | E11: ของเสีย/ปรับลดในช่วง (รายการ) | F11: มูลค่าอุปกรณ์รวม (บาท)
A12: =SUM(tblItems[มูลค่าคงเหลือ (บาท)]) -> 797.68 | B12: =COUNTIF(tblItems[สถานะ],"ใกล้หมด") -> 0 | C12: =COUNTIF(tblItems[สถานะ],"หมด") -> 31 | D12: =SUMIFS(tblPurchases[ราคารวม (บาท)],tblPurchases[วันที่],">="&$B$4,tblPurchases[วันที่],"<="&$D$4) -> 797.68 | E12: =COUNTIFS(tblAdjust[วันที่],">="&$B$4,tblAdjust[วันที่],"<="&$D$4,tblAdjust[จำนวน (+เพิ่ม / -ลด)],"<0") -> 0 | F12: =SUMPRODUCT(tblEquip[ราคา (บาท)],tblEquip[จำนวน]) -> 4756.28
A14: ยอดขายแยกเมนู (ช่วงที่เลือก) | J14: ⚠ สินค้าที่ต้องสั่งซื้อ (ใกล้หมด/หมด)
A15: เมนู | B15: ชื่อไทย | C15: แก้ว | D15: ยอดขาย (บาท) | E15: ต้นทุน (บาท) | F15: กำไร (บาท) | G15: GP % | H15: สัดส่วนยอดขาย | J15: ลำดับ | K15: รหัสสินค้า | L15: ชื่อสินค้า | M15: คงเหลือ (หน่วยใช้) | N15: หน่วยใช้ | O15: สถานะ
A16: =IF(Lists!$A$2="","",Lists!$A$2) -> Original | B16: =IF(A16="","",Lists!$B$2) -> ชาไทยเย็น | C16: =IF(A16="","",SUMIFS(tblSales[จำนวนแก้ว],tblSales[เมนู],A16,tblSales[วันที่],">="&$B$4,tblSales[วันที่],"<="&$D$4)) -> 0 | D16: =IF(A16="","",SUMIFS(tblSales[ยอดขาย (บาท)],tblSales[เมนู],A16,tblSales[วันที่],">="&$B$4,tblSales[วันที่],"<="&$D$4)) -> 0 | E16: =IF(A16="","",SUMIFS(tblSales[ต้นทุนรวม (บาท)],tblSales[เมนู],A16,tblSales[วันที่],">="&$B$4,tblSales[วันที่],"<="&$D$4)) -> 0 | F16: =IF(A16="","",D16-E16) -> 0 | G16: =IF(A16="","",IFERROR(F16/D16,0)) -> 0 | H16: =IF(A16="","",IFERROR(D16/$B$8,0)) -> 0 | J16: 1 | K16: =IFERROR(INDEX(tblItems[รหัสสินค้า],MATCH(J16,tblItems[ลำดับแจ้งเตือน],0)),"") -> RM-TEA-01 | L16: =IF(K16="","",INDEX(tblItems[ชื่อสินค้า],MATCH(K16,tblItems[รหัสสินค้า],0))) -> ชาไทยผงปรุงสำเร็จ ฉลากแดง | M16: =IF(K16="","",INDEX(tblItems[คงเหลือ (หน่วยใช้)],MATCH(K16,tblItems[รหัสสินค้า],0))) -> 0 | N16: =IF(K16="","",INDEX(tblItems[หน่วยใช้],MATCH(K16,tblItems[รหัสสินค้า],0))) -> g | O16: =IF(K16="","",INDEX(tblItems[สถานะ],MATCH(K16,tblItems[รหัสสินค้า],0))) -> หมด
A17: =IF(Lists!$A$3="","",Lists!$A$3) -> Latte | B17: =IF(A17="","",Lists!$B$3) -> ชาไทยนมสด | C17: =IF(A17="","",SUMIFS(tblSales[จำนวนแก้ว],tblSales[เมนู],A17,tblSales[วันที่],">="&$B$4,tblSales[วันที่],"<="&$D$4)) -> 0 | D17: =IF(A17="","",SUMIFS(tblSales[ยอดขาย (บาท)],tblSales[เมนู],A17,tblSales[วันที่],">="&$B$4,tblSales[วันที่],"<="&$D$4)) -> 0 | E17: =IF(A17="","",SUMIFS(tblSales[ต้นทุนรวม (บาท)],tblSales[เมนู],A17,tblSales[วันที่],">="&$B$4,tblSales[วันที่],"<="&$D$4)) -> 0 | F17: =IF(A17="","",D17-E17) -> 0 | G17: =IF(A17="","",IFERROR(F17/D17,0)) -> 0 | H17: =IF(A17="","",IFERROR(D17/$B$8,0)) -> 0 | J17: 2 | K17: =IFERROR(INDEX(tblItems[รหัสสินค้า],MATCH(J17,tblItems[ลำดับแจ้งเตือน],0)),"") -> RM-TEA-02 | L17: =IF(K17="","",INDEX(tblItems[ชื่อสินค้า],MATCH(K17,tblItems[รหัสสินค้า],0))) -> ใบชาใต้ รินชา สูตร 3 | M17: =IF(K17="","",INDEX(tblItems[คงเหลือ (หน่วยใช้)],MATCH(K17,tblItems[รหัสสินค้า],0))) -> 0 | N17: =IF(K17="","",INDEX(tblItems[หน่วยใช้],MATCH(K17,tblItems[รหัสสินค้า],0))) -> g | O17: =IF(K17="","",INDEX(tblItems[สถานะ],MATCH(K17,tblItems[รหัสสินค้า],0))) -> หมด
A18: =IF(Lists!$A$4="","",Lists!$A$4) -> Cream Cheese | B18: =IF(A18="","",Lists!$B$4) -> ชาไทยครีมชีสโฟม | C18: =IF(A18="","",SUMIFS(tblSales[จำนวนแก้ว],tblSales[เมนู],A18,tblSales[วันที่],">="&$B$4,tblSales[วันที่],"<="&$D$4)) -> 0 | D18: =IF(A18="","",SUMIFS(tblSales[ยอดขาย (บาท)],tblSales[เมนู],A18,tblSales[วันที่],">="&$B$4,tblSales[วันที่],"<="&$D$4)) -> 0 | E18: =IF(A18="","",SUMIFS(tblSales[ต้นทุนรวม (บาท)],tblSales[เมนู],A18,tblSales[วันที่],">="&$B$4,tblSales[วันที่],"<="&$D$4)) -> 0 | F18: =IF(A18="","",D18-E18) -> 0 | G18: =IF(A18="","",IFERROR(F18/D18,0)) -> 0 | H18: =IF(A18="","",IFERROR(D18/$B$8,0)) -> 0 | J18: 3 | K18: =IFERROR(INDEX(tblItems[รหัสสินค้า],MATCH(J18,tblItems[ลำดับแจ้งเตือน],0)),"") -> RM-TEA-03 | L18: =IF(K18="","",INDEX(tblItems[ชื่อสินค้า],MATCH(K18,tblItems[รหัสสินค้า],0))) -> ชาเขียวผง ฉลากเขียว | M18: =IF(K18="","",INDEX(tblItems[คงเหลือ (หน่วยใช้)],MATCH(K18,tblItems[รหัสสินค้า],0))) -> 0 | N18: =IF(K18="","",INDEX(tblItems[หน่วยใช้],MATCH(K18,tblItems[รหัสสินค้า],0))) -> g | O18: =IF(K18="","",INDEX(tblItems[สถานะ],MATCH(K18,tblItems[รหัสสินค้า],0))) -> หมด
A19: =IF(Lists!$A$5="","",Lists!$A$5) -> Whip Cheese | B19: =IF(A19="","",Lists!$B$5) -> ชาไทยวิปชีส | C19: =IF(A19="","",SUMIFS(tblSales[จำนวนแก้ว],tblSales[เมนู],A19,tblSales[วันที่],">="&$B$4,tblSales[วันที่],"<="&$D$4)) -> 0 | D19: =IF(A19="","",SUMIFS(tblSales[ยอดขาย (บาท)],tblSales[เมนู],A19,tblSales[วันที่],">="&$B$4,tblSales[วันที่],"<="&$D$4)) -> 0 | E19: =IF(A19="","",SUMIFS(tblSales[ต้นทุนรวม (บาท)],tblSales[เมนู],A19,tblSales[วันที่],">="&$B$4,tblSales[วันที่],"<="&$D$4)) -> 0 | F19: =IF(A19="","",D19-E19) -> 0 | G19: =IF(A19="","",IFERROR(F19/D19,0)) -> 0 | H19: =IF(A19="","",IFERROR(D19/$B$8,0)) -> 0 | J19: 4 | K19: =IFERROR(INDEX(tblItems[รหัสสินค้า],MATCH(J19,tblItems[ลำดับแจ้งเตือน],0)),"") -> RM-TEA-04 | L19: =IF(K19="","",INDEX(tblItems[ชื่อสินค้า],MATCH(K19,tblItems[รหัสสินค้า],0))) -> ใบชาเขียวไม่มีกลิ่นมะลิ รินชา | M19: =IF(K19="","",INDEX(tblItems[คงเหลือ (หน่วยใช้)],MATCH(K19,tblItems[รหัสสินค้า],0))) -> 0 | N19: =IF(K19="","",INDEX(tblItems[หน่วยใช้],MATCH(K19,tblItems[รหัสสินค้า],0))) -> g | O19: =IF(K19="","",INDEX(tblItems[สถานะ],MATCH(K19,tblItems[รหัสสินค้า],0))) -> หมด
A20: =IF(Lists!$A$6="","",Lists!$A$6) -> Orange Latte | B20: =IF(A20="","",Lists!$B$6) -> ชาไทยส้ม | C20: =IF(A20="","",SUMIFS(tblSales[จำนวนแก้ว],tblSales[เมนู],A20,tblSales[วันที่],">="&$B$4,tblSales[วันที่],"<="&$D$4)) -> 0 | D20: =IF(A20="","",SUMIFS(tblSales[ยอดขาย (บาท)],tblSales[เมนู],A20,tblSales[วันที่],">="&$B$4,tblSales[วันที่],"<="&$D$4)) -> 0 | E20: =IF(A20="","",SUMIFS(tblSales[ต้นทุนรวม (บาท)],tblSales[เมนู],A20,tblSales[วันที่],">="&$B$4,tblSales[วันที่],"<="&$D$4)) -> 0 | F20: =IF(A20="","",D20-E20) -> 0 | G20: =IF(A20="","",IFERROR(F20/D20,0)) -> 0 | H20: =IF(A20="","",IFERROR(D20/$B$8,0)) -> 0 | J20: 5 | K20: =IFERROR(INDEX(tblItems[รหัสสินค้า],MATCH(J20,tblItems[ลำดับแจ้งเตือน],0)),"") -> RM-SWT-01 | L20: =IF(K20="","",INDEX(tblItems[ชื่อสินค้า],MATCH(K20,tblItems[รหัสสินค้า],0))) -> น้ำตาลทราย | M20: =IF(K20="","",INDEX(tblItems[คงเหลือ (หน่วยใช้)],MATCH(K20,tblItems[รหัสสินค้า],0))) -> 0 | N20: =IF(K20="","",INDEX(tblItems[หน่วยใช้],MATCH(K20,tblItems[รหัสสินค้า],0))) -> g | O20: =IF(K20="","",INDEX(tblItems[สถานะ],MATCH(K20,tblItems[รหัสสินค้า],0))) -> หมด
A21: =IF(Lists!$A$7="","",Lists!$A$7) -> Cocoa | B21: =IF(A21="","",Lists!$B$7) -> ชาไทยโกโก้ | C21: =IF(A21="","",SUMIFS(tblSales[จำนวนแก้ว],tblSales[เมนู],A21,tblSales[วันที่],">="&$B$4,tblSales[วันที่],"<="&$D$4)) -> 0 | D21: =IF(A21="","",SUMIFS(tblSales[ยอดขาย (บาท)],tblSales[เมนู],A21,tblSales[วันที่],">="&$B$4,tblSales[วันที่],"<="&$D$4)) -> 0 | E21: =IF(A21="","",SUMIFS(tblSales[ต้นทุนรวม (บาท)],tblSales[เมนู],A21,tblSales[วันที่],">="&$B$4,tblSales[วันที่],"<="&$D$4)) -> 0 | F21: =IF(A21="","",D21-E21) -> 0 | G21: =IF(A21="","",IFERROR(F21/D21,0)) -> 0 | H21: =IF(A21="","",IFERROR(D21/$B$8,0)) -> 0 | J21: 6 | K21: =IFERROR(INDEX(tblItems[รหัสสินค้า],MATCH(J21,tblItems[ลำดับแจ้งเตือน],0)),"") -> RM-SEA-01 | L21: =IF(K21="","",INDEX(tblItems[ชื่อสินค้า],MATCH(K21,tblItems[รหัสสินค้า],0))) -> เกลือป่น | M21: =IF(K21="","",INDEX(tblItems[คงเหลือ (หน่วยใช้)],MATCH(K21,tblItems[รหัสสินค้า],0))) -> 0 | N21: =IF(K21="","",INDEX(tblItems[หน่วยใช้],MATCH(K21,tblItems[รหัสสินค้า],0))) -> g | O21: =IF(K21="","",INDEX(tblItems[สถานะ],MATCH(K21,tblItems[รหัสสินค้า],0))) -> หมด
A22: =IF(Lists!$A$8="","",Lists!$A$8) -> Thai Tea Frappe | B22: =IF(A22="","",Lists!$B$8) -> ชาไทยปั่น | C22: =IF(A22="","",SUMIFS(tblSales[จำนวนแก้ว],tblSales[เมนู],A22,tblSales[วันที่],">="&$B$4,tblSales[วันที่],"<="&$D$4)) -> 0 | D22: =IF(A22="","",SUMIFS(tblSales[ยอดขาย (บาท)],tblSales[เมนู],A22,tblSales[วันที่],">="&$B$4,tblSales[วันที่],"<="&$D$4)) -> 0 | E22: =IF(A22="","",SUMIFS(tblSales[ต้นทุนรวม (บาท)],tblSales[เมนู],A22,tblSales[วันที่],">="&$B$4,tblSales[วันที่],"<="&$D$4)) -> 0 | F22: =IF(A22="","",D22-E22) -> 0 | G22: =IF(A22="","",IFERROR(F22/D22,0)) -> 0 | H22: =IF(A22="","",IFERROR(D22/$B$8,0)) -> 0 | J22: 7 | K22: =IFERROR(INDEX(tblItems[รหัสสินค้า],MATCH(J22,tblItems[ลำดับแจ้งเตือน],0)),"") -> RM-MLK-01 | L22: =IF(K22="","",INDEX(tblItems[ชื่อสินค้า],MATCH(K22,tblItems[รหัสสินค้า],0))) -> นมสดรสจืด UHT | M22: =IF(K22="","",INDEX(tblItems[คงเหลือ (หน่วยใช้)],MATCH(K22,tblItems[รหัสสินค้า],0))) -> 0 | N22: =IF(K22="","",INDEX(tblItems[หน่วยใช้],MATCH(K22,tblItems[รหัสสินค้า],0))) -> ml | O22: =IF(K22="","",INDEX(tblItems[สถานะ],MATCH(K22,tblItems[รหัสสินค้า],0))) -> หมด
A23: =IF(Lists!$A$9="","",Lists!$A$9) -> Coconut Frappe | B23: =IF(A23="","",Lists!$B$9) -> ชาไทยมะพร้าวปั่น | C23: =IF(A23="","",SUMIFS(tblSales[จำนวนแก้ว],tblSales[เมนู],A23,tblSales[วันที่],">="&$B$4,tblSales[วันที่],"<="&$D$4)) -> 0 | D23: =IF(A23="","",SUMIFS(tblSales[ยอดขาย (บาท)],tblSales[เมนู],A23,tblSales[วันที่],">="&$B$4,tblSales[วันที่],"<="&$D$4)) -> 0 | E23: =IF(A23="","",SUMIFS(tblSales[ต้นทุนรวม (บาท)],tblSales[เมนู],A23,tblSales[วันที่],">="&$B$4,tblSales[วันที่],"<="&$D$4)) -> 0 | F23: =IF(A23="","",D23-E23) -> 0 | G23: =IF(A23="","",IFERROR(F23/D23,0)) -> 0 | H23: =IF(A23="","",IFERROR(D23/$B$8,0)) -> 0 | J23: 8 | K23: =IFERROR(INDEX(tblItems[รหัสสินค้า],MATCH(J23,tblItems[ลำดับแจ้งเตือน],0)),"") -> RM-MLK-02 | L23: =IF(K23="","",INDEX(tblItems[ชื่อสินค้า],MATCH(K23,tblItems[รหัสสินค้า],0))) -> นมข้นจืด | M23: =IF(K23="","",INDEX(tblItems[คงเหลือ (หน่วยใช้)],MATCH(K23,tblItems[รหัสสินค้า],0))) -> 0 | N23: =IF(K23="","",INDEX(tblItems[หน่วยใช้],MATCH(K23,tblItems[รหัสสินค้า],0))) -> ml | O23: =IF(K23="","",INDEX(tblItems[สถานะ],MATCH(K23,tblItems[รหัสสินค้า],0))) -> หมด
A24: =IF(Lists!$A$10="","",Lists!$A$10) -> Honey Milk | B24: =IF(A24="","",Lists!$B$10) -> ชาไทยนมสดน้ำผึ้ง | C24: =IF(A24="","",SUMIFS(tblSales[จำนวนแก้ว],tblSales[เมนู],A24,tblSales[วันที่],">="&$B$4,tblSales[วันที่],"<="&$D$4)) -> 0 | D24: =IF(A24="","",SUMIFS(tblSales[ยอดขาย (บาท)],tblSales[เมนู],A24,tblSales[วันที่],">="&$B$4,tblSales[วันที่],"<="&$D$4)) -> 0 | E24: =IF(A24="","",SUMIFS(tblSales[ต้นทุนรวม (บาท)],tblSales[เมนู],A24,tblSales[วันที่],">="&$B$4,tblSales[วันที่],"<="&$D$4)) -> 0 | F24: =IF(A24="","",D24-E24) -> 0 | G24: =IF(A24="","",IFERROR(F24/D24,0)) -> 0 | H24: =IF(A24="","",IFERROR(D24/$B$8,0)) -> 0 | J24: 9 | K24: =IFERROR(INDEX(tblItems[รหัสสินค้า],MATCH(J24,tblItems[ลำดับแจ้งเตือน],0)),"") -> RM-MLK-03 | L24: =IF(K24="","",INDEX(tblItems[ชื่อสินค้า],MATCH(K24,tblItems[รหัสสินค้า],0))) -> นมข้นหวาน | M24: =IF(K24="","",INDEX(tblItems[คงเหลือ (หน่วยใช้)],MATCH(K24,tblItems[รหัสสินค้า],0))) -> 0 | N24: =IF(K24="","",INDEX(tblItems[หน่วยใช้],MATCH(K24,tblItems[รหัสสินค้า],0))) -> ml | O24: =IF(K24="","",INDEX(tblItems[สถานะ],MATCH(K24,tblItems[รหัสสินค้า],0))) -> หมด
A25: =IF(Lists!$A$11="","",Lists!$A$11) -> Coconut Tea | B25: =IF(A25="","",Lists!$B$11) -> ชาไทยมะพร้าวน้ำหอม (เย็น) | C25: =IF(A25="","",SUMIFS(tblSales[จำนวนแก้ว],tblSales[เมนู],A25,tblSales[วันที่],">="&$B$4,tblSales[วันที่],"<="&$D$4)) -> 0 | D25: =IF(A25="","",SUMIFS(tblSales[ยอดขาย (บาท)],tblSales[เมนู],A25,tblSales[วันที่],">="&$B$4,tblSales[วันที่],"<="&$D$4)) -> 0 | E25: =IF(A25="","",SUMIFS(tblSales[ต้นทุนรวม (บาท)],tblSales[เมนู],A25,tblSales[วันที่],">="&$B$4,tblSales[วันที่],"<="&$D$4)) -> 0 | F25: =IF(A25="","",D25-E25) -> 0 | G25: =IF(A25="","",IFERROR(F25/D25,0)) -> 0 | H25: =IF(A25="","",IFERROR(D25/$B$8,0)) -> 0 | J25: 10 | K25: =IFERROR(INDEX(tblItems[รหัสสินค้า],MATCH(J25,tblItems[ลำดับแจ้งเตือน],0)),"") -> RM-SWT-02 | L25: =IF(K25="","",INDEX(tblItems[ชื่อสินค้า],MATCH(K25,tblItems[รหัสสินค้า],0))) -> น้ำผึ้ง | M25: =IF(K25="","",INDEX(tblItems[คงเหลือ (หน่วยใช้)],MATCH(K25,tblItems[รหัสสินค้า],0))) -> 0 | N25: =IF(K25="","",INDEX(tblItems[หน่วยใช้],MATCH(K25,tblItems[รหัสสินค้า],0))) -> ml | O25: =IF(K25="","",INDEX(tblItems[สถานะ],MATCH(K25,tblItems[รหัสสินค้า],0))) -> หมด
A26: =IF(Lists!$A$12="","",Lists!$A$12) -> Lemon Tea | B26: =IF(A26="","",Lists!$B$12) -> ชามะนาว | C26: =IF(A26="","",SUMIFS(tblSales[จำนวนแก้ว],tblSales[เมนู],A26,tblSales[วันที่],">="&$B$4,tblSales[วันที่],"<="&$D$4)) -> 0 | D26: =IF(A26="","",SUMIFS(tblSales[ยอดขาย (บาท)],tblSales[เมนู],A26,tblSales[วันที่],">="&$B$4,tblSales[วันที่],"<="&$D$4)) -> 0 | E26: =IF(A26="","",SUMIFS(tblSales[ต้นทุนรวม (บาท)],tblSales[เมนู],A26,tblSales[วันที่],">="&$B$4,tblSales[วันที่],"<="&$D$4)) -> 0 | F26: =IF(A26="","",D26-E26) -> 0 | G26: =IF(A26="","",IFERROR(F26/D26,0)) -> 0 | H26: =IF(A26="","",IFERROR(D26/$B$8,0)) -> 0 | J26: 11 | K26: =IFERROR(INDEX(tblItems[รหัสสินค้า],MATCH(J26,tblItems[ลำดับแจ้งเตือน],0)),"") -> RM-POW-01 | L26: =IF(K26="","",INDEX(tblItems[ชื่อสินค้า],MATCH(K26,tblItems[รหัสสินค้า],0))) -> ผงโกโก้ | M26: =IF(K26="","",INDEX(tblItems[คงเหลือ (หน่วยใช้)],MATCH(K26,tblItems[รหัสสินค้า],0))) -> 0 | N26: =IF(K26="","",INDEX(tblItems[หน่วยใช้],MATCH(K26,tblItems[รหัสสินค้า],0))) -> g | O26: =IF(K26="","",INDEX(tblItems[สถานะ],MATCH(K26,tblItems[รหัสสินค้า],0))) -> หมด
A27: =IF(Lists!$A$13="","",Lists!$A$13) -> Green Tea | B27: =IF(A27="","",Lists!$B$13) -> ชาเขียวเย็น | C27: =IF(A27="","",SUMIFS(tblSales[จำนวนแก้ว],tblSales[เมนู],A27,tblSales[วันที่],">="&$B$4,tblSales[วันที่],"<="&$D$4)) -> 0 | D27: =IF(A27="","",SUMIFS(tblSales[ยอดขาย (บาท)],tblSales[เมนู],A27,tblSales[วันที่],">="&$B$4,tblSales[วันที่],"<="&$D$4)) -> 0 | E27: =IF(A27="","",SUMIFS(tblSales[ต้นทุนรวม (บาท)],tblSales[เมนู],A27,tblSales[วันที่],">="&$B$4,tblSales[วันที่],"<="&$D$4)) -> 0 | F27: =IF(A27="","",D27-E27) -> 0 | G27: =IF(A27="","",IFERROR(F27/D27,0)) -> 0 | H27: =IF(A27="","",IFERROR(D27/$B$8,0)) -> 0 | J27: 12 | K27: =IFERROR(INDEX(tblItems[รหัสสินค้า],MATCH(J27,tblItems[ลำดับแจ้งเตือน],0)),"") -> RM-JUI-01 | L27: =IF(K27="","",INDEX(tblItems[ชื่อสินค้า],MATCH(K27,tblItems[รหัสสินค้า],0))) -> น้ำส้ม 100% | M27: =IF(K27="","",INDEX(tblItems[คงเหลือ (หน่วยใช้)],MATCH(K27,tblItems[รหัสสินค้า],0))) -> 0 | N27: =IF(K27="","",INDEX(tblItems[หน่วยใช้],MATCH(K27,tblItems[รหัสสินค้า],0))) -> ml | O27: =IF(K27="","",INDEX(tblItems[สถานะ],MATCH(K27,tblItems[รหัสสินค้า],0))) -> หมด
A28: =IF(Lists!$A$14="","",Lists!$A$14) -> Green Coconut | B28: =IF(A28="","",Lists!$B$14) -> ชาเขียวมะพร้าว | C28: =IF(A28="","",SUMIFS(tblSales[จำนวนแก้ว],tblSales[เมนู],A28,tblSales[วันที่],">="&$B$4,tblSales[วันที่],"<="&$D$4)) -> 0 | D28: =IF(A28="","",SUMIFS(tblSales[ยอดขาย (บาท)],tblSales[เมนู],A28,tblSales[วันที่],">="&$B$4,tblSales[วันที่],"<="&$D$4)) -> 0 | E28: =IF(A28="","",SUMIFS(tblSales[ต้นทุนรวม (บาท)],tblSales[เมนู],A28,tblSales[วันที่],">="&$B$4,tblSales[วันที่],"<="&$D$4)) -> 0 | F28: =IF(A28="","",D28-E28) -> 0 | G28: =IF(A28="","",IFERROR(F28/D28,0)) -> 0 | H28: =IF(A28="","",IFERROR(D28/$B$8,0)) -> 0 | J28: 13 | K28: =IFERROR(INDEX(tblItems[รหัสสินค้า],MATCH(J28,tblItems[ลำดับแจ้งเตือน],0)),"") -> RM-JUI-02 | L28: =IF(K28="","",INDEX(tblItems[ชื่อสินค้า],MATCH(K28,tblItems[รหัสสินค้า],0))) -> น้ำมะพร้าวน้ำหอม 100% | M28: =IF(K28="","",INDEX(tblItems[คงเหลือ (หน่วยใช้)],MATCH(K28,tblItems[รหัสสินค้า],0))) -> 0 | N28: =IF(K28="","",INDEX(tblItems[หน่วยใช้],MATCH(K28,tblItems[รหัสสินค้า],0))) -> ml | O28: =IF(K28="","",INDEX(tblItems[สถานะ],MATCH(K28,tblItems[รหัสสินค้า],0))) -> หมด
A29: =IF(Lists!$A$15="","",Lists!$A$15) -> Green Honey Milk | B29: =IF(A29="","",Lists!$B$15) -> ชาเขียวนมสดน้ำผึ้ง | C29: =IF(A29="","",SUMIFS(tblSales[จำนวนแก้ว],tblSales[เมนู],A29,tblSales[วันที่],">="&$B$4,tblSales[วันที่],"<="&$D$4)) -> 0 | D29: =IF(A29="","",SUMIFS(tblSales[ยอดขาย (บาท)],tblSales[เมนู],A29,tblSales[วันที่],">="&$B$4,tblSales[วันที่],"<="&$D$4)) -> 0 | E29: =IF(A29="","",SUMIFS(tblSales[ต้นทุนรวม (บาท)],tblSales[เมนู],A29,tblSales[วันที่],">="&$B$4,tblSales[วันที่],"<="&$D$4)) -> 0 | F29: =IF(A29="","",D29-E29) -> 0 | G29: =IF(A29="","",IFERROR(F29/D29,0)) -> 0 | H29: =IF(A29="","",IFERROR(D29/$B$8,0)) -> 0 | J29: 14 | K29: =IFERROR(INDEX(tblItems[รหัสสินค้า],MATCH(J29,tblItems[ลำดับแจ้งเตือน],0)),"") -> RM-MLK-04 | L29: =IF(K29="","",INDEX(tblItems[ชื่อสินค้า],MATCH(K29,tblItems[รหัสสินค้า],0))) -> กะทิ UHT | M29: =IF(K29="","",INDEX(tblItems[คงเหลือ (หน่วยใช้)],MATCH(K29,tblItems[รหัสสินค้า],0))) -> 0 | N29: =IF(K29="","",INDEX(tblItems[หน่วยใช้],MATCH(K29,tblItems[รหัสสินค้า],0))) -> ml | O29: =IF(K29="","",INDEX(tblItems[สถานะ],MATCH(K29,tblItems[รหัสสินค้า],0))) -> หมด
A30: =IF(Lists!$A$16="","",Lists!$A$16) -> Green Berry Soda | B30: =IF(A30="","",Lists!$B$16) -> ชาเขียวสตรอว์เบอร์รี่โซดา | C30: =IF(A30="","",SUMIFS(tblSales[จำนวนแก้ว],tblSales[เมนู],A30,tblSales[วันที่],">="&$B$4,tblSales[วันที่],"<="&$D$4)) -> 0 | D30: =IF(A30="","",SUMIFS(tblSales[ยอดขาย (บาท)],tblSales[เมนู],A30,tblSales[วันที่],">="&$B$4,tblSales[วันที่],"<="&$D$4)) -> 0 | E30: =IF(A30="","",SUMIFS(tblSales[ต้นทุนรวม (บาท)],tblSales[เมนู],A30,tblSales[วันที่],">="&$B$4,tblSales[วันที่],"<="&$D$4)) -> 0 | F30: =IF(A30="","",D30-E30) -> 0 | G30: =IF(A30="","",IFERROR(F30/D30,0)) -> 0 | H30: =IF(A30="","",IFERROR(D30/$B$8,0)) -> 0 | J30: 15 | K30: =IFERROR(INDEX(tblItems[รหัสสินค้า],MATCH(J30,tblItems[ลำดับแจ้งเตือน],0)),"") -> RM-SAU-01 | L30: =IF(K30="","",INDEX(tblItems[ชื่อสินค้า],MATCH(K30,tblItems[รหัสสินค้า],0))) -> ซอสสตรอว์เบอร์รี่ | M30: =IF(K30="","",INDEX(tblItems[คงเหลือ (หน่วยใช้)],MATCH(K30,tblItems[รหัสสินค้า],0))) -> 0 | N30: =IF(K30="","",INDEX(tblItems[หน่วยใช้],MATCH(K30,tblItems[รหัสสินค้า],0))) -> g | O30: =IF(K30="","",INDEX(tblItems[สถานะ],MATCH(K30,tblItems[รหัสสินค้า],0))) -> หมด
A31: =IF(Lists!$A$17="","",Lists!$A$17) -> Green Tea Frappe | B31: =IF(A31="","",Lists!$B$17) -> ชาเขียวปั่น | C31: =IF(A31="","",SUMIFS(tblSales[จำนวนแก้ว],tblSales[เมนู],A31,tblSales[วันที่],">="&$B$4,tblSales[วันที่],"<="&$D$4)) -> 0 | D31: =IF(A31="","",SUMIFS(tblSales[ยอดขาย (บาท)],tblSales[เมนู],A31,tblSales[วันที่],">="&$B$4,tblSales[วันที่],"<="&$D$4)) -> 0 | E31: =IF(A31="","",SUMIFS(tblSales[ต้นทุนรวม (บาท)],tblSales[เมนู],A31,tblSales[วันที่],">="&$B$4,tblSales[วันที่],"<="&$D$4)) -> 0 | F31: =IF(A31="","",D31-E31) -> 0 | G31: =IF(A31="","",IFERROR(F31/D31,0)) -> 0 | H31: =IF(A31="","",IFERROR(D31/$B$8,0)) -> 0
A32: =IF(Lists!$A$18="","",Lists!$A$18) -> Green Latte | B32: =IF(A32="","",Lists!$B$18) -> ชาเขียวนมสด (มัทฉะลาเต้) | C32: =IF(A32="","",SUMIFS(tblSales[จำนวนแก้ว],tblSales[เมนู],A32,tblSales[วันที่],">="&$B$4,tblSales[วันที่],"<="&$D$4)) -> 0 | D32: =IF(A32="","",SUMIFS(tblSales[ยอดขาย (บาท)],tblSales[เมนู],A32,tblSales[วันที่],">="&$B$4,tblSales[วันที่],"<="&$D$4)) -> 0 | E32: =IF(A32="","",SUMIFS(tblSales[ต้นทุนรวม (บาท)],tblSales[เมนู],A32,tblSales[วันที่],">="&$B$4,tblSales[วันที่],"<="&$D$4)) -> 0 | F32: =IF(A32="","",D32-E32) -> 0 | G32: =IF(A32="","",IFERROR(F32/D32,0)) -> 0 | H32: =IF(A32="","",IFERROR(D32/$B$8,0)) -> 0
A33: =IF(Lists!$A$19="","",Lists!$A$19) -> Green Lemon Tea | B33: =IF(A33="","",Lists!$B$19) -> ชาเขียวมะนาว | C33: =IF(A33="","",SUMIFS(tblSales[จำนวนแก้ว],tblSales[เมนู],A33,tblSales[วันที่],">="&$B$4,tblSales[วันที่],"<="&$D$4)) -> 0 | D33: =IF(A33="","",SUMIFS(tblSales[ยอดขาย (บาท)],tblSales[เมนู],A33,tblSales[วันที่],">="&$B$4,tblSales[วันที่],"<="&$D$4)) -> 0 | E33: =IF(A33="","",SUMIFS(tblSales[ต้นทุนรวม (บาท)],tblSales[เมนู],A33,tblSales[วันที่],">="&$B$4,tblSales[วันที่],"<="&$D$4)) -> 0 | F33: =IF(A33="","",D33-E33) -> 0 | G33: =IF(A33="","",IFERROR(F33/D33,0)) -> 0 | H33: =IF(A33="","",IFERROR(D33/$B$8,0)) -> 0
A34: =IF(Lists!$A$20="","",Lists!$A$20) -> Green Honey Lemon | B34: =IF(A34="","",Lists!$B$20) -> ชาเขียวน้ำผึ้งมะนาว | C34: =IF(A34="","",SUMIFS(tblSales[จำนวนแก้ว],tblSales[เมนู],A34,tblSales[วันที่],">="&$B$4,tblSales[วันที่],"<="&$D$4)) -> 0 | D34: =IF(A34="","",SUMIFS(tblSales[ยอดขาย (บาท)],tblSales[เมนู],A34,tblSales[วันที่],">="&$B$4,tblSales[วันที่],"<="&$D$4)) -> 0 | E34: =IF(A34="","",SUMIFS(tblSales[ต้นทุนรวม (บาท)],tblSales[เมนู],A34,tblSales[วันที่],">="&$B$4,tblSales[วันที่],"<="&$D$4)) -> 0 | F34: =IF(A34="","",D34-E34) -> 0 | G34: =IF(A34="","",IFERROR(F34/D34,0)) -> 0 | H34: =IF(A34="","",IFERROR(D34/$B$8,0)) -> 0
A35: =IF(Lists!$A$21="","",Lists!$A$21) -> Green Cream Cheese | B35: =IF(A35="","",Lists!$B$21) -> ชาเขียวครีมชีสโฟม | C35: =IF(A35="","",SUMIFS(tblSales[จำนวนแก้ว],tblSales[เมนู],A35,tblSales[วันที่],">="&$B$4,tblSales[วันที่],"<="&$D$4)) -> 0 | D35: =IF(A35="","",SUMIFS(tblSales[ยอดขาย (บาท)],tblSales[เมนู],A35,tblSales[วันที่],">="&$B$4,tblSales[วันที่],"<="&$D$4)) -> 0 | E35: =IF(A35="","",SUMIFS(tblSales[ต้นทุนรวม (บาท)],tblSales[เมนู],A35,tblSales[วันที่],">="&$B$4,tblSales[วันที่],"<="&$D$4)) -> 0 | F35: =IF(A35="","",D35-E35) -> 0 | G35: =IF(A35="","",IFERROR(F35/D35,0)) -> 0 | H35: =IF(A35="","",IFERROR(D35/$B$8,0)) -> 0
A36: =IF(Lists!$A$22="","",Lists!$A$22) -> Pure Matcha Premium | B36: =IF(A36="","",Lists!$B$22) -> เพียวมัทฉะ (มัทฉะน้ำใส) | C36: =IF(A36="","",SUMIFS(tblSales[จำนวนแก้ว],tblSales[เมนู],A36,tblSales[วันที่],">="&$B$4,tblSales[วันที่],"<="&$D$4)) -> 0 | D36: =IF(A36="","",SUMIFS(tblSales[ยอดขาย (บาท)],tblSales[เมนู],A36,tblSales[วันที่],">="&$B$4,tblSales[วันที่],"<="&$D$4)) -> 0 | E36: =IF(A36="","",SUMIFS(tblSales[ต้นทุนรวม (บาท)],tblSales[เมนู],A36,tblSales[วันที่],">="&$B$4,tblSales[วันที่],"<="&$D$4)) -> 0 | F36: =IF(A36="","",D36-E36) -> 0 | G36: =IF(A36="","",IFERROR(F36/D36,0)) -> 0 | H36: =IF(A36="","",IFERROR(D36/$B$8,0)) -> 0
A37: =IF(Lists!$A$23="","",Lists!$A$23) -> Matcha Latte Premium | B37: =IF(A37="","",Lists!$B$23) -> มัทฉะลาเต้พรีเมียม | C37: =IF(A37="","",SUMIFS(tblSales[จำนวนแก้ว],tblSales[เมนู],A37,tblSales[วันที่],">="&$B$4,tblSales[วันที่],"<="&$D$4)) -> 0 | D37: =IF(A37="","",SUMIFS(tblSales[ยอดขาย (บาท)],tblSales[เมนู],A37,tblSales[วันที่],">="&$B$4,tblSales[วันที่],"<="&$D$4)) -> 0 | E37: =IF(A37="","",SUMIFS(tblSales[ต้นทุนรวม (บาท)],tblSales[เมนู],A37,tblSales[วันที่],">="&$B$4,tblSales[วันที่],"<="&$D$4)) -> 0 | F37: =IF(A37="","",D37-E37) -> 0 | G37: =IF(A37="","",IFERROR(F37/D37,0)) -> 0 | H37: =IF(A37="","",IFERROR(D37/$B$8,0)) -> 0
A38: =IF(Lists!$A$24="","",Lists!$A$24) -> Matcha Coconut Premium | B38: =IF(A38="","",Lists!$B$24) -> มัทฉะน้ำมะพร้าวพรีเมียม | C38: =IF(A38="","",SUMIFS(tblSales[จำนวนแก้ว],tblSales[เมนู],A38,tblSales[วันที่],">="&$B$4,tblSales[วันที่],"<="&$D$4)) -> 0 | D38: =IF(A38="","",SUMIFS(tblSales[ยอดขาย (บาท)],tblSales[เมนู],A38,tblSales[วันที่],">="&$B$4,tblSales[วันที่],"<="&$D$4)) -> 0 | E38: =IF(A38="","",SUMIFS(tblSales[ต้นทุนรวม (บาท)],tblSales[เมนู],A38,tblSales[วันที่],">="&$B$4,tblSales[วันที่],"<="&$D$4)) -> 0 | F38: =IF(A38="","",D38-E38) -> 0 | G38: =IF(A38="","",IFERROR(F38/D38,0)) -> 0 | H38: =IF(A38="","",IFERROR(D38/$B$8,0)) -> 0
A39: =IF(Lists!$A$25="","",Lists!$A$25) -> Matcha Strawberry Premium | B39: =IF(A39="","",Lists!$B$25) -> สตรอว์เบอร์รี่มัทฉะลาเต้พรีเมียม | C39: =IF(A39="","",SUMIFS(tblSales[จำนวนแก้ว],tblSales[เมนู],A39,tblSales[วันที่],">="&$B$4,tblSales[วันที่],"<="&$D$4)) -> 0 | D39: =IF(A39="","",SUMIFS(tblSales[ยอดขาย (บาท)],tblSales[เมนู],A39,tblSales[วันที่],">="&$B$4,tblSales[วันที่],"<="&$D$4)) -> 0 | E39: =IF(A39="","",SUMIFS(tblSales[ต้นทุนรวม (บาท)],tblSales[เมนู],A39,tblSales[วันที่],">="&$B$4,tblSales[วันที่],"<="&$D$4)) -> 0 | F39: =IF(A39="","",D39-E39) -> 0 | G39: =IF(A39="","",IFERROR(F39/D39,0)) -> 0 | H39: =IF(A39="","",IFERROR(D39/$B$8,0)) -> 0
A40: ="รวม" -> รวม | C40: =SUM(C16:C39) -> 0 | D40: =SUM(D16:D39) -> 0 | E40: =SUM(E16:E39) -> 0 | F40: =SUM(F16:F39) -> 0 | G40: =IFERROR(F40/D40,0) -> 0 | H40: =IFERROR(D40/$B$8,0) -> 0
A42: ยอดขายรายวัน 7 วันล่าสุด
A43: วันที่ | B43: แก้ว | C43: ยอดขาย (บาท) | D43: กำไร (บาท) | E43: GP %
A44: =TODAY()-6 -> 46276 | B44: =SUMIFS(tblSales[จำนวนแก้ว],tblSales[วันที่],A44) -> 0 | C44: =SUMIFS(tblSales[ยอดขาย (บาท)],tblSales[วันที่],A44) -> 0 | D44: =SUMIFS(tblSales[กำไร (บาท)],tblSales[วันที่],A44) -> 0 | E44: =IFERROR(D44/C44,0) -> 0
A45: =TODAY()-5 -> 46277 | B45: =SUMIFS(tblSales[จำนวนแก้ว],tblSales[วันที่],A45) -> 0 | C45: =SUMIFS(tblSales[ยอดขาย (บาท)],tblSales[วันที่],A45) -> 0 | D45: =SUMIFS(tblSales[กำไร (บาท)],tblSales[วันที่],A45) -> 0 | E45: =IFERROR(D45/C45,0) -> 0
...

Sheet คำนวณสูตร
B2: DA-YO Recipe Calculator
B3: เลือกเมนู → ขนาด → ระดับความหวาน ระบบจะคำนวณสูตร ต้นทุน และกำไรให้อัตโนมัติ
B5: เมนู | C5: Original | D5: =IFERROR(INDEX(Lists!$B$2:$B$60,MATCH($C$5,Lists!$A$2:$A$60,0)),"") -> ชาไทยเย็น
B6: ขนาด (oz) | C6: 20 oz
B7: ระดับความหวาน | C7: 50%
B9: หมายเหตุ: | C9: =IFERROR(INDEX(ตารางรวม!Y:Y,MATCH($C$5&"|"&$C$6&"|"&$C$7,ตารางรวม!$Z:$Z,0)),"") -> [20 oz = 16 oz x 1.25] แก้: เพิ่มชาเบส 100→130 ml และคุมของเหลวรวมเป็น ~190 ml (เดิม 145–160 ml น้อยเกินไป แก้ไม่เต็ม ลูกค้าเห็นชัดตอนรับแก้ว) · รอบ 6: เบสชาไทยไม่มีน้ำตาลแล้ว จึงเติมน้ำเชื่อม 1:1 ชดเชย = 0.128 × ปริมาณเบสชา เพื่อให้ความหวานเท่าสูตรเดิม
B12: ส่วนผสม | C12: ปริมาณ | D12: หน่วย
B13: ชาไทยเบส | C13: =IFERROR(INDEX(ตารางรวม!D:D,MATCH($C$5&"|"&$C$6&"|"&$C$7,ตารางรวม!$Z:$Z,0)),"-") -> 162.5 | D13: ml
B14: ชาเขียวเบส | C14: =IFERROR(INDEX(ตารางรวม!E:E,MATCH($C$5&"|"&$C$6&"|"&$C$7,ตารางรวม!$Z:$Z,0)),"-") -> 0 | D14: ml
B15: นมสด | C15: =IFERROR(INDEX(ตารางรวม!F:F,MATCH($C$5&"|"&$C$6&"|"&$C$7,ตารางรวม!$Z:$Z,0)),"-") -> 0 | D15: ml
B16: นมข้นจืด | C16: =IFERROR(INDEX(ตารางรวม!G:G,MATCH($C$5&"|"&$C$6&"|"&$C$7,ตารางรวม!$Z:$Z,0)),"-") -> 57.5 | D16: ml
B17: นมข้นหวาน | C17: =IFERROR(INDEX(ตารางรวม!H:H,MATCH($C$5&"|"&$C$6&"|"&$C$7,ตารางรวม!$Z:$Z,0)),"-") -> 20 | D17: ml
B18: น้ำเชื่อม 1:1 | C18: =IFERROR(INDEX(ตารางรวม!I:I,MATCH($C$5&"|"&$C$6&"|"&$C$7,ตารางรวม!$Z:$Z,0)),"-") -> 20.8 | D18: ml
B19: น้ำผึ้งเจือจาง 2:1 | C19: =IFERROR(INDEX(ตารางรวม!J:J,MATCH($C$5&"|"&$C$6&"|"&$C$7,ตารางรวม!$Z:$Z,0)),"-") -> 0 | D19: ml
B20: โกโก้ผง | C20: =IFERROR(INDEX(ตารางรวม!K:K,MATCH($C$5&"|"&$C$6&"|"&$C$7,ตารางรวม!$Z:$Z,0)),"-") -> 0 | D20: g
B21: น้ำส้มคั้น | C21: =IFERROR(INDEX(ตารางรวม!L:L,MATCH($C$5&"|"&$C$6&"|"&$C$7,ตารางรวม!$Z:$Z,0)),"-") -> 0 | D21: ml
B22: เบสมะพร้าว | C22: =IFERROR(INDEX(ตารางรวม!M:M,MATCH($C$5&"|"&$C$6&"|"&$C$7,ตารางรวม!$Z:$Z,0)),"-") -> 0 | D22: ml
B23: ซอสสตรอว์เบอร์รี่ | C23: =IFERROR(INDEX(ตารางรวม!N:N,MATCH($C$5&"|"&$C$6&"|"&$C$7,ตารางรวม!$Z:$Z,0)),"-") -> 0 | D23: g
B24: น้ำมะนาว | C24: =IFERROR(INDEX(ตารางรวม!O:O,MATCH($C$5&"|"&$C$6&"|"&$C$7,ตารางรวม!$Z:$Z,0)),"-") -> 0 | D24: ml
B25: โซดา | C25: =IFERROR(INDEX(ตารางรวม!P:P,MATCH($C$5&"|"&$C$6&"|"&$C$7,ตารางรวม!$Z:$Z,0)),"-") -> 0 | D25: ml
B26: ครีมชีส / วิปชีสโฟม | C26: =IFERROR(INDEX(ตารางรวม!Q:Q,MATCH($C$5&"|"&$C$6&"|"&$C$7,ตารางรวม!$Z:$Z,0)),"-") -> 0 | D26: g
B27: น้ำแข็ง | C27: =IFERROR(INDEX(ตารางรวม!R:R,MATCH($C$5&"|"&$C$6&"|"&$C$7,ตารางรวม!$Z:$Z,0)),"-") -> 300 | D27: g
B28: มัทฉะช็อต (พรีเมียม) | C28: =IFERROR(INDEX(ตารางรวม!S:S,MATCH($C$5&"|"&$C$6&"|"&$C$7,ตารางรวม!$Z:$Z,0)),"-") -> 0
B29: น้ำดื่ม | C29: =IFERROR(INDEX(ตารางรวม!T:T,MATCH($C$5&"|"&$C$6&"|"&$C$7,ตารางรวม!$Z:$Z,0)),"-") -> 0
B31: ของเหลวรวม | C31: =IFERROR(INDEX(ตารางรวม!U:U,MATCH($C$5&"|"&$C$6&"|"&$C$7,ตารางรวม!$Z:$Z,0)),"-") -> 260.8 | D31: ml
B32: ต้นทุนวัตถุดิบ + บรรจุภัณฑ์ | C32: =IFERROR(INDEX(ตารางรวม!V:V,MATCH($C$5&"|"&$C$6&"|"&$C$7,ตารางรวม!$Z:$Z,0)),"-") -> 18.04 | D32: บาท
B33: ราคาขาย | C33: =IFERROR(INDEX(ตารางรวม!W:W,MATCH($C$5&"|"&$C$6&"|"&$C$7,ตารางรวม!$Z:$Z,0)),"-") -> 50 | D33: บาท | E33: เกณฑ์ GP (แก้ได้)
B34: กำไรขั้นต้นต่อแก้ว | C34: =IFERROR(C33-C32,"") -> 31.96 | D34: บาท | E34: ผ่าน ≥ | F34: 0.6
B35: GP % | C35: =IFERROR(INDEX(ตารางรวม!X:X,MATCH($C$5&"|"&$C$6&"|"&$C$7,ตารางรวม!$Z:$Z,0)),"-") -> 0.6392 | E35: เฝ้าระวัง ≥ | F35: 0.55
B36: เช็ค GP | C36: =IF(C35="-","",IF(C35>=$F$34,"ผ่าน (>="&TEXT($F$34,"0%")&")",IF(C35>=$F$35,"เฝ้าระวัง ("&TEXT($F$35,"0%")&"-"&TEXT($F$34,"0%")&")","ต่ำเกินไป - ปรับราคาหรือสูตร"))) -> ผ่าน (>=60%) | E36: ต่ำกว่านี้ = ปรับราคา/สูตร
B38: วิธีใช้: คลิกช่องสีเขียว (C5, C6, C7) แล้วเลือกจาก Dropdown
B39: แก้ราคาวัตถุดิบ/ราคาขาย ที่ชีต 'ต้นทุนและราคา' · แก้ปริมาณสูตร ที่ชีต 'ข้อมูลสูตร'

Sheet ข้อมูลสูตร
A1: Key | B1: เมนู | C1: ขนาด | D1: ความหวาน | E1: ชาไทยเบส (ml) | F1: ชาเขียวเบส (ml) | G1: นมสด (ml) | H1: นมข้นจืด (ml) | I1: นมข้นหวาน (ml) | J1: น้ำเชื่อม (ml) | K1: น้ำผึ้งเจือจาง (ml) | L1: โกโก้ผง (g) | M1: น้ำส้มคั้น (ml) | N1: เบสมะพร้าว (ml) | O1: ซอสสตรอว์เบอร์รี่ (g) | P1: น้ำมะนาว (ml) | Q1: โซดา (ml) | R1: ครีมชีส/วิปชีส (g) | S1: น้ำแข็ง (g) | T1: มัทฉะช็อต (ml) | U1: น้ำดื่ม (ml) | V1: ของเหลวรวม (ml) | W1: ต้นทุน/แก้ว (บาท) | X1: ราคาขาย (บาท) | Y1: GP % | Z1: หมายเหตุ | AB1: ตัวคูนสเกล 20 oz (เทียบ 16 oz) | AD1: ตัวคูณชดเชยน้ำตาลที่ถอดออกจากเบส (ml น้ำเชื่อม 1:1 ต่อ 1 ml เบสชา)
A2: =IF($B2="","",$B2&"|"&$C2&"|"&$D2) -> Original|16 oz|0% | B2: Original | C2: 16 oz | D2: 0% | E2: 130 | F2: 0 | G2: 0 | H2: 58 | I2: 0 | J2: 0 | K2: 0 | L2: 0 | M2: 0 | N2: 0 | O2: 0 | P2: 0 | Q2: 0 | R2: 0 | S2: 240 | T2: 0 | U2: 0 | V2: =E2+F2+G2+H2+I2+J2+K2+M2+N2+P2+Q2+T2+U2 -> 188 | W2: =ROUND(E2*ต้นทุนและราคา!$C$4+F2*ต้นทุนและราคา!$C$5+G2*ต้นทุนและราคา!$C$6+H2*ต้นทุนและราคา!$C$7+I2*ต้นทุนและราคา!$C$8+J2*ต้นทุนและราคา!$C$9+K2*ต้นทุนและราคา!$C$10+L2*ต้นทุนและราคา!$C$11+M2*ต้นทุนและราคา!$C$12+N2*ต้นทุนและราคา!$C$13+O2*ต้นทุนและราคา!$C$14+P2*ต้นทุนและราคา!$C$15+Q2*ต้นทุนและราคา!$C$16+R2*ต้นทุนและราคา!$C$17+S2*ต้นทุนและราคา!$C$18+T2*ต้นทุนและราคา!$C$19+U2*ต้นทุนและราคา!$C$20+IF($C2="16 oz",ต้นทุนและราคา!$C$21,IF($C2="20 oz",ต้นทุนและราคา!$C$22,ต้นทุนและราคา!$C$23)),2) -> 14.26 | X2: {=IFERROR(INDEX(ต้นทุนและราคา!$C$26:$E$101,MATCH($B2,ต้นทุนและราคา!$A$26:$A$101,0),IF($C2="16 oz",1,IF($C2="20 oz",2,3))),"")} -> 45 | Y2: =IFERROR(($X2-$W2)/$X2,"") -> 0.68311111 | Z2: แก้: เพิ่มชาเบส 100→130 ml และคุมของเหลวรวมเป็น ~190 ml (เดิม 145–160 ml น้อยเกินไป แก้ไม่เต็ม ลูกค้าเห็นชัดตอนรับแก้ว) · รอบ 6: เบสชาไทยไม่มีน้ำตาลแล้ว — ระดับ 0% จึงไม่มีน้ำตาลเพิ่มจริง (เดิมยังมีน้ำตาลจากเบส ~10 g) รสจะเปลี่ยนจากเดิม | AB2: 1.25 | AD2: 0.128
A3: =IF($B3="","",$B3&"|"&$C3&"|"&$D3) -> Original|16 oz|25% | B3: Original | C3: 16 oz | D3: 25% | E3: 130 | F3: 0 | G3: 0 | H3: 52 | I3: 8 | J3: 16.6 | K3: 0 | L3: 0 | M3: 0 | N3: 0 | O3: 0 | P3: 0 | Q3: 0 | R3: 0 | S3: 240 | T3: 0 | U3: 0 | V3: =E3+F3+G3+H3+I3+J3+K3+M3+N3+P3+Q3+T3+U3 -> 206.6 | W3: =ROUND(E3*ต้นทุนและราคา!$C$4+F3*ต้นทุนและราคา!$C$5+G3*ต้นทุนและราคา!$C$6+H3*ต้นทุนและราคา!$C$7+I3*ต้นทุนและราคา!$C$8+J3*ต้นทุนและราคา!$C$9+K3*ต้นทุนและราคา!$C$10+L3*ต้นทุนและราคา!$C$11+M3*ต้นทุนและราคา!$C$12+N3*ต้นทุนและราคา!$C$13+O3*ต้นทุนและราคา!$C$14+P3*ต้นทุนและราคา!$C$15+Q3*ต้นทุนและราคา!$C$16+R3*ต้นทุนและราคา!$C$17+S3*ต้นทุนและราคา!$C$18+T3*ต้นทุนและราคา!$C$19+U3*ต้นทุนและราคา!$C$20+IF($C3="16 oz",ต้นทุนและราคา!$C$21,IF($C3="20 oz",ต้นทุนและราคา!$C$22,ต้นทุนและราคา!$C$23)),2) -> 14.64 | X3: {=IFERROR(INDEX(ต้นทุนและราคา!$C$26:$E$101,MATCH($B3,ต้นทุนและราคา!$A$26:$A$101,0),IF($C3="16 oz",1,IF($C3="20 oz",2,3))),"")} -> 45 | Y3: =IFERROR(($X3-$W3)/$X3,"") -> 0.67466667 | Z3: แก้: เพิ่มชาเบส 100→130 ml และคุมของเหลวรวมเป็น ~190 ml (เดิม 145–160 ml น้อยเกินไป แก้ไม่เต็ม ลูกค้าเห็นชัดตอนรับแก้ว) · รอบ 6: เบสชาไทยไม่มีน้ำตาลแล้ว จึงเติมน้ำเชื่อม 1:1 ชดเชย = 0.128 × ปริมาณเบสชา เพื่อให้ความหวานเท่าสูตรเดิม
A4: =IF($B4="","",$B4&"|"&$C4&"|"&$D4) -> Original|16 oz|50% | B4: Original | C4: 16 oz | D4: 50% | E4: 130 | F4: 0 | G4: 0 | H4: 46 | I4: 16 | J4: 16.6 | K4: 0 | L4: 0 | M4: 0 | N4: 0 | O4: 0 | P4: 0 | Q4: 0 | R4: 0 | S4: 240 | T4: 0 | U4: 0 | V4: =E4+F4+G4+H4+I4+J4+K4+M4+N4+P4+Q4+T4+U4 -> 208.6 | W4: =ROUND(E4*ต้นทุนและราคา!$C$4+F4*ต้นทุนและราคา!$C$5+G4*ต้นทุนและราคา!$C$6+H4*ต้นทุนและราคา!$C$7+I4*ต้นทุนและราคา!$C$8+J4*ต้นทุนและราคา!$C$9+K4*ต้นทุนและราคา!$C$10+L4*ต้นทุนและราคา!$C$11+M4*ต้นทุนและราคา!$C$12+N4*ต้นทุนและราคา!$C$13+O4*ต้นทุนและราคา!$C$14+P4*ต้นทุนและราคา!$C$15+Q4*ต้นทุนและราคา!$C$16+R4*ต้นทุนและราคา!$C$17+S4*ต้นทุนและราคา!$C$18+T4*ต้นทุนและราคา!$C$19+U4*ต้นทุนและราคา!$C$20+IF($C4="16 oz",ต้นทุนและราคา!$C$21,IF($C4="20 oz",ต้นทุนและราคา!$C$22,ต้นทุนและราคา!$C$23)),2) -> 14.75 | X4: {=IFERROR(INDEX(ต้นทุนและราคา!$C$26:$E$101,MATCH($B4,ต้นทุนและราคา!$A$26:$A$101,0),IF($C4="16 oz",1,IF($C4="20 oz",2,3))),"")} -> 45 | Y4: =IFERROR(($X4-$W4)/$X4,"") -> 0.67222222 | Z4: แก้: เพิ่มชาเบส 100→130 ml และคุมของเหลวรวมเป็น ~190 ml (เดิม 145–160 ml น้อยเกินไป แก้ไม่เต็ม ลูกค้าเห็นชัดตอนรับแก้ว) · รอบ 6: เบสชาไทยไม่มีน้ำตาลแล้ว จึงเติมน้ำเชื่อม 1:1 ชดเชย = 0.128 × ปริมาณเบสชา เพื่อให้ความหวานเท่าสูตรเดิม
A5: =IF($B5="","",$B5&"|"&$C5&"|"&$D5) -> Original|16 oz|75% | B5: Original | C5: 16 oz | D5: 75% | E5: 130 | F5: 0 | G5: 0 | H5: 40 | I5: 24 | J5: 16.6 | K5: 0 | L5: 0 | M5: 0 | N5: 0 | O5: 0 | P5: 0 | Q5: 0 | R5: 0 | S5: 240 | T5: 0 | U5: 0 | V5: =E5+F5+G5+H5+I5+J5+K5+M5+N5+P5+Q5+T5+U5 -> 210.6 | W5: =ROUND(E5*ต้นทุนและราคา!$C$4+F5*ต้นทุนและราคา!$C$5+G5*ต้นทุนและราคา!$C$6+H5*ต้นทุนและราคา!$C$7+I5*ต้นทุนและราคา!$C$8+J5*ต้นทุนและราคา!$C$9+K5*ต้นทุนและราคา!$C$10+L5*ต้นทุนและราคา!$C$11+M5*ต้นทุนและราคา!$C$12+N5*ต้นทุนและราคา!$C$13+O5*ต้นทุนและราคา!$C$14+P5*ต้นทุนและราคา!$C$15+Q5*ต้นทุนและราคา!$C$16+R5*ต้นทุนและราคา!$C$17+S5*ต้นทุนและราคา!$C$18+T5*ต้นทุนและราคา!$C$19+U5*ต้นทุนและราคา!$C$20+IF($C5="16 oz",ต้นทุนและราคา!$C$21,IF($C5="20 oz",ต้นทุนและราคา!$C$22,ต้นทุนและราคา!$C$23)),2) -> 14.86 | X5: {=IFERROR(INDEX(ต้นทุนและราคา!$C$26:$E$101,MATCH($B5,ต้นทุนและราคา!$A$26:$A$101,0),IF($C5="16 oz",1,IF($C5="20 oz",2,3))),"")} -> 45 | Y5: =IFERROR(($X5-$W5)/$X5,"") -> 0.66977778 | Z5: แก้: เพิ่มชาเบส 100→130 ml และคุมของเหลวรวมเป็น ~190 ml (เดิม 145–160 ml น้อยเกินไป แก้ไม่เต็ม ลูกค้าเห็นชัดตอนรับแก้ว) · รอบ 6: เบสชาไทยไม่มีน้ำตาลแล้ว จึงเติมน้ำเชื่อม 1:1 ชดเชย = 0.128 × ปริมาณเบสชา เพื่อให้ความหวานเท่าสูตรเดิม
A6: =IF($B6="","",$B6&"|"&$C6&"|"&$D6) -> Original|16 oz|100% | B6: Original | C6: 16 oz | D6: 100% | E6: 130 | F6: 0 | G6: 0 | H6: 34 | I6: 32 | J6: 16.6 | K6: 0 | L6: 0 | M6: 0 | N6: 0 | O6: 0 | P6: 0 | Q6: 0 | R6: 0 | S6: 240 | T6: 0 | U6: 0 | V6: =E6+F6+G6+H6+I6+J6+K6+M6+N6+P6+Q6+T6+U6 -> 212.6 | W6: =ROUND(E6*ต้นทุนและราคา!$C$4+F6*ต้นทุนและราคา!$C$5+G6*ต้นทุนและราคา!$C$6+H6*ต้นทุนและราคา!$C$7+I6*ต้นทุนและราคา!$C$8+J6*ต้นทุนและราคา!$C$9+K6*ต้นทุนและราคา!$C$10+L6*ต้นทุนและราคา!$C$11+M6*ต้นทุนและราคา!$C$12+N6*ต้นทุนและราคา!$C$13+O6*ต้นทุนและราคา!$C$14+P6*ต้นทุนและราคา!$C$15+Q6*ต้นทุนและราคา!$C$16+R6*ต้นทุนและราคา!$C$17+S6*ต้นทุนและราคา!$C$18+T6*ต้นทุนและราคา!$C$19+U6*ต้นทุนและราคา!$C$20+IF($C6="16 oz",ต้นทุนและราคา!$C$21,IF($C6="20 oz",ต้นทุนและราคา!$C$22,ต้นทุนและราคา!$C$23)),2) -> 14.97 | X6: {=IFERROR(INDEX(ต้นทุนและราคา!$C$26:$E$101,MATCH($B6,ต้นทุนและราคา!$A$26:$A$101,0),IF($C6="16 oz",1,IF($C6="20 oz",2,3))),"")} -> 45 | Y6: =IFERROR(($X6-$W6)/$X6,"") -> 0.66733333 | Z6: แก้: เพิ่มชาเบส 100→130 ml และคุมของเหลวรวมเป็น ~190 ml (เดิม 145–160 ml น้อยเกินไป แก้ไม่เต็ม ลูกค้าเห็นชัดตอนรับแก้ว) · รอบ 6: เบสชาไทยไม่มีน้ำตาลแล้ว จึงเติมน้ำเชื่อม 1:1 ชดเชย = 0.128 × ปริมาณเบสชา เพื่อให้ความหวานเท่าสูตรเดิม
A7: =IF($B7="","",$B7&"|"&$C7&"|"&$D7) -> Original|22 oz|0% | B7: Original | C7: 22 oz | D7: 0% | E7: 179 | F7: 0 | G7: 0 | H7: 80 | I7: 0 | J7: 0 | K7: 0 | L7: 0 | M7: 0 | N7: 0 | O7: 0 | P7: 0 | Q7: 0 | R7: 0 | S7: 330 | T7: 0 | U7: 0 | V7: =E7+F7+G7+H7+I7+J7+K7+M7+N7+P7+Q7+T7+U7 -> 259 | W7: =ROUND(E7*ต้นทุนและราคา!$C$4+F7*ต้นทุนและราคา!$C$5+G7*ต้นทุนและราคา!$C$6+H7*ต้นทุนและราคา!$C$7+I7*ต้นทุนและราคา!$C$8+J7*ต้นทุนและราคา!$C$9+K7*ต้นทุนและราคา!$C$10+L7*ต้นทุนและราคา!$C$11+M7*ต้นทุนและราคา!$C$12+N7*ต้นทุนและราคา!$C$13+O7*ต้นทุนและราคา!$C$14+P7*ต้นทุนและราคา!$C$15+Q7*ต้นทุนและราคา!$C$16+R7*ต้นทุนและราคา!$C$17+S7*ต้นทุนและราคา!$C$18+T7*ต้นทุนและราคา!$C$19+U7*ต้นทุนและราคา!$C$20+IF($C7="16 oz",ต้นทุนและราคา!$C$21,IF($C7="20 oz",ต้นทุนและราคา!$C$22,ต้นทุนและราคา!$C$23)),2) -> 18.93 | X7: {=IFERROR(INDEX(ต้นทุนและราคา!$C$26:$E$101,MATCH($B7,ต้นทุนและราคา!$A$26:$A$101,0),IF($C7="16 oz",1,IF($C7="20 oz",2,3))),"")} -> 55 | Y7: =IFERROR(($X7-$W7)/$X7,"") -> 0.65581818 | Z7: แก้: เพิ่มชาเบส 100→130 ml และคุมของเหลวรวมเป็น ~190 ml (เดิม 145–160 ml น้อยเกินไป แก้ไม่เต็ม ลูกค้าเห็นชัดตอนรับแก้ว) · รอบ 6: เบสชาไทยไม่มีน้ำตาลแล้ว — ระดับ 0% จึงไม่มีน้ำตาลเพิ่มจริง (เดิมยังมีน้ำตาลจากเบส ~10 g) รสจะเปลี่ยนจากเดิม
A8: =IF($B8="","",$B8&"|"&$C8&"|"&$D8) -> Original|22 oz|25% | B8: Original | C8: 22 oz | D8: 25% | E8: 179 | F8: 0 | G8: 0 | H8: 71.5 | I8: 11 | J8: 22.9 | K8: 0 | L8: 0 | M8: 0 | N8: 0 | O8: 0 | P8: 0 | Q8: 0 | R8: 0 | S8: 330 | T8: 0 | U8: 0 | V8: =E8+F8+G8+H8+I8+J8+K8+M8+N8+P8+Q8+T8+U8 -> 284.4 | W8: =ROUND(E8*ต้นทุนและราคา!$C$4+F8*ต้นทุนและราคา!$C$5+G8*ต้นทุนและราคา!$C$6+H8*ต้นทุนและราคา!$C$7+I8*ต้นทุนและราคา!$C$8+J8*ต้นทุนและราคา!$C$9+K8*ต้นทุนและราคา!$C$10+L8*ต้นทุนและราคา!$C$11+M8*ต้นทุนและราคา!$C$12+N8*ต้นทุนและราคา!$C$13+O8*ต้นทุนและราคา!$C$14+P8*ต้นทุนและราคา!$C$15+Q8*ต้นทุนและราคา!$C$16+R8*ต้นทุนและราคา!$C$17+S8*ต้นทุนและราคา!$C$18+T8*ต้นทุนและราคา!$C$19+U8*ต้นทุนและราคา!$C$20+IF($C8="16 oz",ต้นทุนและราคา!$C$21,IF($C8="20 oz",ต้นทุนและราคา!$C$22,ต้นทุนและราคา!$C$23)),2) -> 19.44 | X8: {=IFERROR(INDEX(ต้นทุนและราคา!$C$26:$E$101,MATCH($B8,ต้นทุนและราคา!$A$26:$A$101,0),IF($C8="16 oz",1,IF($C8="20 oz",2,3))),"")} -> 55 | Y8: =IFERROR(($X8-$W8)/$X8,"") -> 0.64654545 | Z8: แก้: เพิ่มชาเบส 100→130 ml และคุมของเหลวรวมเป็น ~190 ml (เดิม 145–160 ml น้อยเกินไป แก้ไม่เต็ม ลูกค้าเห็นชัดตอนรับแก้ว) · รอบ 6: เบสชาไทยไม่มีน้ำตาลแล้ว จึงเติมน้ำเชื่อม 1:1 ชดเชย = 0.128 × ปริมาณเบสชา เพื่อให้ความหวานเท่าสูตรเดิม
A9: =IF($B9="","",$B9&"|"&$C9&"|"&$D9) -> Original|22 oz|50% | B9: Original | C9: 22 oz | D9: 50% | E9: 179 | F9: 0 | G9: 0 | H9: 63 | I9: 22 | J9: 22.9 | K9: 0 | L9: 0 | M9: 0 | N9: 0 | O9: 0 | P9: 0 | Q9: 0 | R9: 0 | S9: 330 | T9: 0 | U9: 0 | V9: =E9+F9+G9+H9+I9+J9+K9+M9+N9+P9+Q9+T9+U9 -> 286.9 | W9: =ROUND(E9*ต้นทุนและราคา!$C$4+F9*ต้นทุนและราคา!$C$5+G9*ต้นทุนและราคา!$C$6+H9*ต้นทุนและราคา!$C$7+I9*ต้นทุนและราคา!$C$8+J9*ต้นทุนและราคา!$C$9+K9*ต้นทุนและราคา!$C$10+L9*ต้นทุนและราคา!$C$11+M9*ต้นทุนและราคา!$C$12+N9*ต้นทุนและราคา!$C$13+O9*ต้นทุนและราคา!$C$14+P9*ต้นทุนและราคา!$C$15+Q9*ต้นทุนและราคา!$C$16+R9*ต้นทุนและราคา!$C$17+S9*ต้นทุนและราคา!$C$18+T9*ต้นทุนและราคา!$C$19+U9*ต้นทุนและราคา!$C$20+IF($C9="16 oz",ต้นทุนและราคา!$C$21,IF($C9="20 oz",ต้นทุนและราคา!$C$22,ต้นทุนและราคา!$C$23)),2) -> 19.57 | X9: {=IFERROR(INDEX(ต้นทุนและราคา!$C$26:$E$101,MATCH($B9,ต้นทุนและราคา!$A$26:$A$101,0),IF($C9="16 oz",1,IF($C9="20 oz",2,3))),"")} -> 55 | Y9: =IFERROR(($X9-$W9)/$X9,"") -> 0.64418182 | Z9: แก้: เพิ่มชาเบส 100→130 ml และคุมของเหลวรวมเป็น ~190 ml (เดิม 145–160 ml น้อยเกินไป แก้ไม่เต็ม ลูกค้าเห็นชัดตอนรับแก้ว) · รอบ 6: เบสชาไทยไม่มีน้ำตาลแล้ว จึงเติมน้ำเชื่อม 1:1 ชดเชย = 0.128 × ปริมาณเบสชา เพื่อให้ความหวานเท่าสูตรเดิม
A10: =IF($B10="","",$B10&"|"&$C10&"|"&$D10) -> Original|22 oz|75% | B10: Original | C10: 22 oz | D10: 75% | E10: 179 | F10: 0 | G10: 0 | H10: 55 | I10: 33 | J10: 22.9 | K10: 0 | L10: 0 | M10: 0 | N10: 0 | O10: 0 | P10: 0 | Q10: 0 | R10: 0 | S10: 330 | T10: 0 | U10: 0 | V10: =E10+F10+G10+H10+I10+J10+K10+M10+N10+P10+Q10+T10+U10 -> 289.9 | W10: =ROUND(E10*ต้นทุนและราคา!$C$4+F10*ต้นทุนและราคา!$C$5+G10*ต้นทุนและราคา!$C$6+H10*ต้นทุนและราคา!$C$7+I10*ต้นทุนและราคา!$C$8+J10*ต้นทุนและราคา!$C$9+K10*ต้นทุนและราคา!$C$10+L10*ต้นทุนและราคา!$C$11+M10*ต้นทุนและราคา!$C$12+N10*ต้นทุนและราคา!$C$13+O10*ต้นทุนและราคา!$C$14+P10*ต้นทุนและราคา!$C$15+Q10*ต้นทุนและราคา!$C$16+R10*ต้นทุนและราคา!$C$17+S10*ต้นทุนและราคา!$C$18+T10*ต้นทุนและราคา!$C$19+U10*ต้นทุนและราคา!$C$20+IF($C10="16 oz",ต้นทุนและราคา!$C$21,IF($C10="20 oz",ต้นทุนและราคา!$C$22,ต้นทุนและราคา!$C$23)),2) -> 19.74 | X10: {=IFERROR(INDEX(ต้นทุนและราคา!$C$26:$E$101,MATCH($B10,ต้นทุนและราคา!$A$26:$A$101,0),IF($C10="16 oz",1,IF($C10="20 oz",2,3))),"")} -> 55 | Y10: =IFERROR(($X10-$W10)/$X10,"") -> 0.64109091 | Z10: แก้: เพิ่มชาเบส 100→130 ml และคุมของเหลวรวมเป็น ~190 ml (เดิม 145–160 ml น้อยเกินไป แก้ไม่เต็ม ลูกค้าเห็นชัดตอนรับแก้ว) · รอบ 6: เบสชาไทยไม่มีน้ำตาลแล้ว จึงเติมน้ำเชื่อม 1:1 ชดเชย = 0.128 × ปริมาณเบสชา เพื่อให้ความหวานเท่าสูตรเดิม
A11: =IF($B11="","",$B11&"|"&$C11&"|"&$D11) -> Original|22 oz|100% | B11: Original | C11: 22 oz | D11: 100% | E11: 179 | F11: 0 | G11: 0 | H11: 47 | I11: 44 | J11: 22.9 | K11: 0 | L11: 0 | M11: 0 | N11: 0 | O11: 0 | P11: 0 | Q11: 0 | R11: 0 | S11: 330 | T11: 0 | U11: 0 | V11: =E11+F11+G11+H11+I11+J11+K11+M11+N11+P11+Q11+T11+U11 -> 292.9 | W11: =ROUND(E11*ต้นทุนและราคา!$C$4+F11*ต้นทุนและราคา!$C$5+G11*ต้นทุนและราคา!$C$6+H11*ต้นทุนและราคา!$C$7+I11*ต้นทุนและราคา!$C$8+J11*ต้นทุนและราคา!$C$9+K11*ต้นทุนและราคา!$C$10+L11*ต้นทุนและราคา!$C$11+M11*ต้นทุนและราคา!$C$12+N11*ต้นทุนและราคา!$C$13+O11*ต้นทุนและราคา!$C$14+P11*ต้นทุนและราคา!$C$15+Q11*ต้นทุนและราคา!$C$16+R11*ต้นทุนและราคา!$C$17+S11*ต้นทุนและราคา!$C$18+T11*ต้นทุนและราคา!$C$19+U11*ต้นทุนและราคา!$C$20+IF($C11="16 oz",ต้นทุนและราคา!$C$21,IF($C11="20 oz",ต้นทุนและราคา!$C$22,ต้นทุนและราคา!$C$23)),2) -> 19.91 | X11: {=IFERROR(INDEX(ต้นทุนและราคา!$C$26:$E$101,MATCH($B11,ต้นทุนและราคา!$A$26:$A$101,0),IF($C11="16 oz",1,IF($C11="20 oz",2,3))),"")} -> 55 | Y11: =IFERROR(($X11-$W11)/$X11,"") -> 0.638 | Z11: แก้: เพิ่มชาเบส 100→130 ml และคุมของเหลวรวมเป็น ~190 ml (เดิม 145–160 ml น้อยเกินไป แก้ไม่เต็ม ลูกค้าเห็นชัดตอนรับแก้ว) · รอบ 6: เบสชาไทยไม่มีน้ำตาลแล้ว จึงเติมน้ำเชื่อม 1:1 ชดเชย = 0.128 × ปริมาณเบสชา เพื่อให้ความหวานเท่าสูตรเดิม
A12: =IF($B12="","",$B12&"|"&$C12&"|"&$D12) -> Latte|16 oz|0% | B12: Latte | C12: 16 oz | D12: 0% | E12: 130 | F12: 0 | G12: 50 | H12: 20 | I12: 0 | J12: 0 | K12: 0 | L12: 0 | M12: 0 | N12: 0 | O12: 0 | P12: 0 | Q12: 0 | R12: 0 | S12: 240 | T12: 0 | U12: 0 | V12: =E12+F12+G12+H12+I12+J12+K12+M12+N12+P12+Q12+T12+U12 -> 200 | W12: =ROUND(E12*ต้นทุนและราคา!$C$4+F12*ต้นทุนและราคา!$C$5+G12*ต้นทุนและราคา!$C$6+H12*ต้นทุนและราคา!$C$7+I12*ต้นทุนและราคา!$C$8+J12*ต้นทุนและราคา!$C$9+K12*ต้นทุนและราคา!$C$10+L12*ต้นทุนและราคา!$C$11+M12*ต้นทุนและราคา!$C$12+N12*ต้นทุนและราคา!$C$13+O12*ต้นทุนและราคา!$C$14+P12*ต้นทุนและราคา!$C$15+Q12*ต้นทุนและราคา!$C$16+R12*ต้นทุนและราคา!$C$17+S12*ต้นทุนและราคา!$C$18+T12*ต้นทุนและราคา!$C$19+U12*ต้นทุนและราคา!$C$20+IF($C12="16 oz",ต้นทุนและราคา!$C$21,IF($C12="20 oz",ต้นทุนและราคา!$C$22,ต้นทุนและราคา!$C$23)),2) -> 13.84 | X12: {=IFERROR(INDEX(ต้นทุนและราคา!$C$26:$E$101,MATCH($B12,ต้นทุนและราคา!$A$26:$A$101,0),IF($C12="16 oz",1,IF($C12="20 oz",2,3))),"")} -> 50 | Y12: =IFERROR(($X12-$W12)/$X12,"") -> 0.7232 | Z12: แก้: เปลี่ยนตัวให้ความหวานจากนมข้นหวาน→น้ำเชื่อม (เมนูชูนมสดไม่ควรเติมนมข้นซ้อนนม) และเพิ่มชาเบส 60→130 ml เพราะไม่มีไขมันครีมเทียมพยุงรสชา · รอบ 6: เบสชาไทยไม่มีน้ำตาลแล้ว — ระดับ 0% จึงไม่มีน้ำตาลเพิ่มจริง (เดิมยังมีน้ำตาลจากเบส ~10 g) รสจะเปลี่ยนจากเดิม
A13: =IF($B13="","",$B13&"|"&$C13&"|"&$D13) -> Latte|16 oz|25% | B13: Latte | C13: 16 oz | D13: 25% | E13: 130 | F13: 0 | G13: 30.4 | H13: 20 | I13: 0 | J13: 23.6 | K13: 0 | L13: 0 | M13: 0 | N13: 0 | O13: 0 | P13: 0 | Q13: 0 | R13: 0 | S13: 240 | T13: 0 | U13: 0 | V13: =E13+F13+G13+H13+I13+J13+K13+M13+N13+P13+Q13+T13+U13 -> 204 | W13: =ROUND(E13*ต้นทุนและราคา!$C$4+F13*ต้นทุนและราคา!$C$5+G13*ต้นทุนและราคา!$C$6+H13*ต้นทุนและราคา!$C$7+I13*ต้นทุนและราคา!$C$8+J13*ต้นทุนและราคา!$C$9+K13*ต้นทุนและราคา!$C$10+L13*ต้นทุนและราคา!$C$11+M13*ต้นทุนและราคา!$C$12+N13*ต้นทุนและราคา!$C$13+O13*ต้นทุนและราคา!$C$14+P13*ต้นทุนและราคา!$C$15+Q13*ต้นทุนและราคา!$C$16+R13*ต้นทุนและราคา!$C$17+S13*ต้นทุนและราคา!$C$18+T13*ต้นทุนและราคา!$C$19+U13*ต้นทุนและราคา!$C$20+IF($C13="16 oz",ต้นทุนและราคา!$C$21,IF($C13="20 oz",ต้นทุนและราคา!$C$22,ต้นทุนและราคา!$C$23)),2) -> 13.3 | X13: {=IFERROR(INDEX(ต้นทุนและราคา!$C$26:$E$101,MATCH($B13,ต้นทุนและราคา!$A$26:$A$101,0),IF($C13="16 oz",1,IF($C13="20 oz",2,3))),"")} -> 50 | Y13: =IFERROR(($X13-$W13)/$X13,"") -> 0.734 | Z13: แก้: เปลี่ยนตัวให้ความหวานจากนมข้นหวาน→น้ำเชื่อม (เมนูชูนมสดไม่ควรเติมนมข้นซ้อนนม) และเพิ่มชาเบส 60→130 ml เพราะไม่มีไขมันครีมเทียมพยุงรสชา · รอบ 6: เบสชาไทยไม่มีน้ำตาลแล้ว จึงเติมน้ำเชื่อม 1:1 ชดเชย และลด นมสด ลงเท่ากัน เพื่อคุมปริมาตรแก้วให้เท่าเดิม
A14: =IF($B14="","",$B14&"|"&$C14&"|"&$D14) -> Latte|16 oz|50% | B14: Latte | C14: 16 oz | D14: 50% | E14: 130 | F14: 0 | G14: 27.4 | H14: 20 | I14: 0 | J14: 30.6 | K14: 0 | L14: 0 | M14: 0 | N14: 0 | O14: 0 | P14: 0 | Q14: 0 | R14: 0 | S14: 240 | T14: 0 | U14: 0 | V14: =E14+F14+G14+H14+I14+J14+K14+M14+N14+P14+Q14+T14+U14 -> 208 | W14: =ROUND(E14*ต้นทุนและราคา!$C$4+F14*ต้นทุนและราคา!$C$5+G14*ต้นทุนและราคา!$C$6+H14*ต้นทุนและราคา!$C$7+I14*ต้นทุนและราคา!$C$8+J14*ต้นทุนและราคา!$C$9+K14*ต้นทุนและราคา!$C$10+L14*ต้นทุนและราคา!$C$11+M14*ต้นทุนและราคา!$C$12+N14*ต้นทุนและราคา!$C$13+O14*ต้นทุนและราคา!$C$14+P14*ต้นทุนและราคา!$C$15+Q14*ต้นทุนและราคา!$C$16+R14*ต้นทุนและราคา!$C$17+S14*ต้นทุนและราคา!$C$18+T14*ต้นทุนและราคา!$C$19+U14*ต้นทุนและราคา!$C$20+IF($C14="16 oz",ต้นทุนและราคา!$C$21,IF($C14="20 oz",ต้นทุนและราคา!$C$22,ต้นทุนและราคา!$C$23)),2) -> 13.27 | X14: {=IFERROR(INDEX(ต้นทุนและราคา!$C$26:$E$101,MATCH($B14,ต้นทุนและราคา!$A$26:$A$101,0),IF($C14="16 oz",1,IF($C14="20 oz",2,3))),"")} -> 50 | Y14: =IFERROR(($X14-$W14)/$X14,"") -> 0.7346 | Z14: แก้: เปลี่ยนตัวให้ความหวานจากนมข้นหวาน→น้ำเชื่อม (เมนูชูนมสดไม่ควรเติมนมข้นซ้อนนม) และเพิ่มชาเบส 60→130 ml เพราะไม่มีไขมันครีมเทียมพยุงรสชา · รอบ 6: เบสชาไทยไม่มีน้ำตาลแล้ว จึงเติมน้ำเชื่อม 1:1 ชดเชย และลด นมสด ลงเท่ากัน เพื่อคุมปริมาตรแก้วให้เท่าเดิม
... A112: =IF($B112="","",$B112&"|"&$C112&"|"&$D112) -> Green Tea|16 oz|0% | B112: Green Tea | C112: 16 oz | D112: 0% | E112: 0 | F112: 135 | G112: 0 | H112: 56 | I112: 0 | J112: 0 | K112: 0 | L112: 0 | M112: 0 | N112: 0 | O112: 0 | P112: 0 | Q112: 0 | R112: 0 | S112: 240 | T112: 0 | U112: 0 | V112: =E112+F112+G112+H112+I112+J112+K112+M112+N112+P112+Q112+T112+U112 -> 191 | W112: =ROUND(E112*ต้นทุนและราคา!$C$4+F112*ต้นทุนและราคา!$C$5+G112*ต้นทุนและราคา!$C$6+H112*ต้นทุนและราคา!$C$7+I112*ต้นทุนและราคา!$C$8+J112*ต้นทุนและราคา!$C$9+K112*ต้นทุนและราคา!$C$10+L112*ต้นทุนและราคา!$C$11+M112*ต้นทุนและราคา!$C$12+N112*ต้นทุนและราคา!$C$13+O112*ต้นทุนและราคา!$C$14+P112*ต้นทุนและราคา!$C$15+Q112*ต้นทุนและราคา!$C$16+R112*ต้นทุนและราคา!$C$17+S112*ต้นทุนและราคา!$C$18+T112*ต้นทุนและราคา!$C$19+U112*ต้นทุนและราคา!$C$20+IF($C112="16 oz",ต้นทุนและราคา!$C$21,IF($C112="20 oz",ต้นทุนและราคา!$C$22,ต้นทุนและราคา!$C$23)),2) -> 14.79 | X112: {=IFERROR(INDEX(ต้นทุนและราคา!$C$26:$E$101,MATCH($B112,ต้นทุนและราคา!$A$26:$A$101,0),IF($C112="16 oz",1,IF($C112="20 oz",2,3))),"")} -> 45 | Y112: =IFERROR(($X112-$W112)/$X112,"") -> 0.67133333 | Z112: เมนูใหม่ — เปิดไลน์ชาเขียว: ลูกค้ามาเป็นคู่/กลุ่มมักสั่งคนละอย่าง ถ้ามีแต่ชาไทยจะเสียยอดครึ่งหนึ่งของทุกกลุ่ม · รอบ 7: เบสชาเขียวไม่มีน้ำตาลแล้ว — ระดับ 0% จึงไม่มีน้ำตาลเพิ่มจริง (เดิมยังมีน้ำตาลจากเบส ~11 g) รสจะเปลี่ยนจากเดิม
A113: =IF($B113="","",$B113&"|"&$C113&"|"&$D113) -> Green Tea|16 oz|25% | B113: Green Tea | C113: 16 oz | D113: 25% | E113: 0 | F113: 135 | G113: 0 | H113: 50 | I113: 8 | J113: =ROUND(0+$AD$2*F113,1) -> 17.3 | K113: 0 | L113: 0 | M113: 0 | N113: 0 | O113: 0 | P113: 0 | Q113: 0 | R113: 0 | S113: 240 | T113: 0 | U113: 0 | V113: =E113+F113+G113+H113+I113+J113+K113+M113+N113+P113+Q113+T113+U113 -> 210.3 | W113: =ROUND(E113*ต้นทุนและราคา!$C$4+F113*ต้นทุนและราคา!$C$5+G113*ต้นทุนและราคา!$C$6+H113*ต้นทุนและราคา!$C$7+I113*ต้นทุนและราคา!$C$8+J113*ต้นทุนและราคา!$C$9+K113*ต้นทุนและราคา!$C$10+L113*ต้นทุนและราคา!$C$11+M113*ต้นทุนและราคา!$C$12+N113*ต้นทุนและราคา!$C$13+O113*ต้นทุนและราคา!$C$14+P113*ต้นทุนและราคา!$C$15+Q113*ต้นทุนและราคา!$C$16+R113*ต้นทุนและราคา!$C$17+S113*ต้นทุนและราคา!$C$18+T113*ต้นทุนและราคา!$C$19+U113*ต้นทุนและราคา!$C$20+IF($C113="16 oz",ต้นทุนและราคา!$C$21,IF($C113="20 oz",ต้นทุนและราคา!$C$22,ต้นทุนและราคา!$C$23)),2) -> 15.19 | X113: {=IFERROR(INDEX(ต้นทุนและราคา!$C$26:$E$101,MATCH($B113,ต้นทุนและราคา!$A$26:$A$101,0),IF($C113="16 oz",1,IF($C113="20 oz",2,3))),"")} -> 45 | Y113: =IFERROR(($X113-$W113)/$X113,"") -> 0.66244444 | Z113: เมนูใหม่ — เปิดไลน์ชาเขียว: ลูกค้ามาเป็นคู่/กลุ่มมักสั่งคนละอย่าง ถ้ามีแต่ชาไทยจะเสียยอดครึ่งหนึ่งของทุกกลุ่ม · รอบ 7: เบสชาเขียวไม่มีน้ำตาลแล้ว จึงเติมน้ำเชื่อม 1:1 ชดเชย = 0.128 × ปริมาณเบสชาเขียว
A114: =IF($B114="","",$B114&"|"&$C114&"|"&$D114) -> Green Tea|16 oz|50% | B114: Green Tea | C114: 16 oz | D114: 50% | E114: 0 | F114: 135 | G114: 0 | H114: 44 | I114: 16 | J114: =ROUND(0+$AD$2*F114,1) -> 17.3 | K114: 0 | L114: 0 | M114: 0 | N114: 0 | O114: 0 | P114: 0 | Q114: 0 | R114: 0 | S114: 240 | T114: 0 | U114: 0 | V114: =E114+F114+G114+H114+I114+J114+K114+M114+N114+P114+Q114+T114+U114 -> 212.3 | W114: =ROUND(E114*ต้นทุนและราคา!$C$4+F114*ต้นทุนและราคา!$C$5+G114*ต้นทุนและราคา!$C$6+H114*ต้นทุนและราคา!$C$7+I114*ต้นทุนและราคา!$C$8+J114*ต้นทุนและราคา!$C$9+K114*ต้นทุนและราคา!$C$10+L114*ต้นทุนและราคา!$C$11+M114*ต้นทุนและราคา!$C$12+N114*ต้นทุนและราคา!$C$13+O114*ต้นทุนและราคา!$C$14+P114*ต้นทุนและราคา!$C$15+Q114*ต้นทุนและราคา!$C$16+R114*ต้นทุนและราคา!$C$17+S114*ต้นทุนและราคา!$C$18+T114*ต้นทุนและราคา!$C$19+U114*ต้นทุนและราคา!$C$20+IF($C114="16 oz",ต้นทุนและราคา!$C$21,IF($C114="20 oz",ต้นทุนและราคา!$C$22,ต้นทุนและราคา!$C$23)),2) -> 15.3 | X114: {=IFERROR(INDEX(ต้นทุนและราคา!$C$26:$E$101,MATCH($B114,ต้นทุนและราคา!$A$26:$A$101,0),IF($C114="16 oz",1,IF($C114="20 oz",2,3))),"")} -> 45 | Y114: =IFERROR(($X114-$W114)/$X114,"") -> 0.66 | Z114: เมนูใหม่ — เปิดไลน์ชาเขียว: ลูกค้ามาเป็นคู่/กลุ่มมักสั่งคนละอย่าง ถ้ามีแต่ชาไทยจะเสียยอดครึ่งหนึ่งของทุกกลุ่ม · รอบ 7: เบสชาเขียวไม่มีน้ำตาลแล้ว จึงเติมน้ำเชื่อม 1:1 ชดเชย = 0.128 × ปริมาณเบสชาเขียว
A115: =IF($B115="","",$B115&"|"&$C115&"|"&$D115) -> Green Tea|16 oz|75% | B115: Green Tea | C115: 16 oz | D115: 75% | E115: 0 | F115: 135 | G115: 0 | H115: 38 | I115: 24 | J115: =ROUND(0+$AD$2*F115,1) -> 17.3 | K115: 0 | L115: 0 | M115: 0 | N115: 0 | O115: 0 | P115: 0 | Q115: 0 | R115: 0 | S115: 240 | T115: 0 | U115: 0 | V115: =E115+F115+G115+H115+I115+J115+K115+M115+N115+P115+Q115+T115+U115 -> 214.3 | W115: =ROUND(E115*ต้นทุนและราคา!$C$4+F115*ต้นทุนและราคา!$C$5+G115*ต้นทุนและราคา!$C$6+H115*ต้นทุนและราคา!$C$7+I115*ต้นทุนและราคา!$C$8+J115*ต้นทุนและราคา!$C$9+K115*ต้นทุนและราคา!$C$10+L115*ต้นทุนและราคา!$C$11+M115*ต้นทุนและราคา!$C$12+N115*ต้นทุนและราคา!$C$13+O115*ต้นทุนและราคา!$C$14+P115*ต้นทุนและราคา!$C$15+Q115*ต้นทุนและราคา!$C$16+R115*ต้นทุนและราคา!$C$17+S115*ต้นทุนและราคา!$C$18+T115*ต้นทุนและราคา!$C$19+U115*ต้นทุนและราคา!$C$20+IF($C115="16 oz",ต้นทุนและราคา!$C$21,IF($C115="20 oz",ต้นทุนและราคา!$C$22,ต้นทุนและราคา!$C$23)),2) -> 15.41 | X115: {=IFERROR(INDEX(ต้นทุนและราคา!$C$26:$E$101,MATCH($B115,ต้นทุนและราคา!$A$26:$A$101,0),IF($C115="16 oz",1,IF($C115="20 oz",2,3))),"")} -> 45 | Y115: =IFERROR(($X115-$W115)/$X115,"") -> 0.65755556 | Z115: เมนูใหม่ — เปิดไลน์ชาเขียว: ลูกค้ามาเป็นคู่/กลุ่มมักสั่งคนละอย่าง ถ้ามีแต่ชาไทยจะเสียยอดครึ่งหนึ่งของทุกกลุ่ม · รอบ 7: เบสชาเขียวไม่มีน้ำตาลแล้ว จึงเติมน้ำเชื่อม 1:1 ชดเชย = 0.128 × ปริมาณเบสชาเขียว
A116: =IF($B116="","",$B116&"|"&$C116&"|"&$D116) -> Green Tea|16 oz|100% | B116: Green Tea | C116: 16 oz | D116: 100% | E116: 0 | F116: 135 | G116: 0 | H116: 32 | I116: 32 | J116: =ROUND(0+$AD$2*F116,1) -> 17.3 | K116: 0 | L116: 0 | M116: 0 | N116: 0 | O116: 0 | P116: 0 | Q116: 0 | R116: 0 | S116: 240 | T116: 0 | U116: 0 | V116: =E116+F116+G116+H116+I116+J116+K116+M116+N116+P116+Q116+T116+U116 -> 216.3 | W116: =ROUND(E116*ต้นทุนและราคา!$C$4+F116*ต้นทุนและราคา!$C$5+G116*ต้นทุนและราคา!$C$6+H116*ต้นทุนและราคา!$C$7+I116*ต้นทุนและราคา!$C$8+J116*ต้นทุนและราคา!$C$9+K116*ต้นทุนและราคา!$C$10+L116*ต้นทุนและราคา!$C$11+M116*ต้นทุนและราคา!$C$12+N116*ต้นทุนและราคา!$C$13+O116*ต้นทุนและราคา!$C$14+P116*ต้นทุนและราคา!$C$15+Q116*ต้นทุนและราคา!$C$16+R116*ต้นทุนและราคา!$C$17+S116*ต้นทุนและราคา!$C$18+T116*ต้นทุนและราคา!$C$19+U116*ต้นทุนและราคา!$C$20+IF($C116="16 oz",ต้นทุนและราคา!$C$21,IF($C116="20 oz",ต้นทุนและราคา!$C$22,ต้นทุนและราคา!$C$23)),2) -> 15.52 | X116: {=IFERROR(INDEX(ต้นทุนและราคา!$C$26:$E$101,MATCH($B116,ต้นทุนและราคา!$A$26:$A$101,0),IF($C116="16 oz",1,IF($C116="20 oz",2,3))),"")} -> 45 | Y116: =IFERROR(($X116-$W116)/$X116,"") -> 0.65511111 | Z116: เมนูใหม่ — เปิดไลน์ชาเขียว: ลูกค้ามาเป็นคู่/กลุ่มมักสั่งคนละอย่าง ถ้ามีแต่ชาไทยจะเสียยอดครึ่งหนึ่งของทุกกลุ่ม · รอบ 7: เบสชาเขียวไม่มีน้ำตาลแล้ว จึงเติมน้ำเชื่อม 1:1 ชดเชย = 0.128 × ปริมาณเบสชาเขียว
A117: =IF($B117="","",$B117&"|"&$C117&"|"&$D117) -> Green Tea|22 oz|0% | B117: Green Tea | C117: 22 oz | D117: 0% | E117: 0 | F117: 185.5 | G117: 0 | H117: 77 | I117: 0 | J117: 0 | K117: 0 | L117: 0 | M117: 0 | N117: 0 | O117: 0 | P117: 0 | Q117: 0 | R117: 0 | S117: 330 | T117: 0 | U117: 0 | V117: =E117+F117+G117+H117+I117+J117+K117+M117+N117+P117+Q117+T117+U117 -> 262.5 | W117: =ROUND(E117*ต้นทุนและราคา!$C$4+F117*ต้นทุนและราคา!$C$5+G117*ต้นทุนและราคา!$C$6+H117*ต้นทุนและราคา!$C$7+I117*ต้นทุนและราคา!$C$8+J117*ต้นทุนและราคา!$C$9+K117*ต้นทุนและราคา!$C$10+L117*ต้นทุนและราคา!$C$11+M117*ต้นทุนและราคา!$C$12+N117*ต้นทุนและราคา!$C$13+O117*ต้นทุนและราคา!$C$14+P117*ต้นทุนและราคา!$C$15+Q117*ต้นทุนและราคา!$C$16+R117*ต้นทุนและราคา!$C$17+S117*ต้นทุนและราคา!$C$18+T117*ต้นทุนและราคา!$C$19+U117*ต้นทุนและราคา!$C$20+IF($C117="16 oz",ต้นทุนและราคา!$C$21,IF($C117="20 oz",ต้นทุนและราคา!$C$22,ต้นทุนและราคา!$C$23)),2) -> 19.64 | X117: {=IFERROR(INDEX(ต้นทุนและราคา!$C$26:$E$101,MATCH($B117,ต้นทุนและราคา!$A$26:$A$101,0),IF($C117="16 oz",1,IF($C117="20 oz",2,3))),"")} -> 55 | Y117: =IFERROR(($X117-$W117)/$X117,"") -> 0.64290909 | Z117: เมนูใหม่ — เปิดไลน์ชาเขียว: ลูกค้ามาเป็นคู่/กลุ่มมักสั่งคนละอย่าง ถ้ามีแต่ชาไทยจะเสียยอดครึ่งหนึ่งของทุกกลุ่ม · รอบ 7: เบสชาเขียวไม่มีน้ำตาลแล้ว — ระดับ 0% จึงไม่มีน้ำตาลเพิ่มจริง (เดิมยังมีน้ำตาลจากเบส ~11 g) รสจะเปลี่ยนจากเดิม
A118: =IF($B118="","",$B118&"|"&$C118&"|"&$D118) -> Green Tea|22 oz|25% | B118: Green Tea | C118: 22 oz | D118: 25% | E118: 0 | F118: 185.5 | G118: 0 | H118: 69 | I118: 11 | J118: =ROUND(0+$AD$2*F118,1) -> 23.7 | K118: 0 | L118: 0 | M118: 0 | N118: 0 | O118: 0 | P118: 0 | Q118: 0 | R118: 0 | S118: 330 | T118: 0 | U118: 0 | V118: =E118+F118+G118+H118+I118+J118+K118+M118+N118+P118+Q118+T118+U118 -> 289.2 | W118: =ROUND(E118*ต้นทุนและราคา!$C$4+F118*ต้นทุนและราคา!$C$5+G118*ต้นทุนและราคา!$C$6+H118*ต้นทุนและราคา!$C$7+I118*ต้นทุนและราคา!$C$8+J118*ต้นทุนและราคา!$C$9+K118*ต้นทุนและราคา!$C$10+L118*ต้นทุนและราคา!$C$11+M118*ต้นทุนและราคา!$C$12+N118*ต้นทุนและราคา!$C$13+O118*ต้นทุนและราคา!$C$14+P118*ต้นทุนและราคา!$C$15+Q118*ต้นทุนและราคา!$C$16+R118*ต้นทุนและราคา!$C$17+S118*ต้นทุนและราคา!$C$18+T118*ต้นทุนและราคา!$C$19+U118*ต้นทุนและราคา!$C$20+IF($C118="16 oz",ต้นทุนและราคา!$C$21,IF($C118="20 oz",ต้นทุนและราคา!$C$22,ต้นทุนและราคา!$C$23)),2) -> 20.2 | X118: {=IFERROR(INDEX(ต้นทุนและราคา!$C$26:$E$101,MATCH($B118,ต้นทุนและราคา!$A$26:$A$101,0),IF($C118="16 oz",1,IF($C118="20 oz",2,3))),"")} -> 55 | Y118: =IFERROR(($X118-$W118)/$X118,"") -> 0.63272727 | Z118: เมนูใหม่ — เปิดไลน์ชาเขียว: ลูกค้ามาเป็นคู่/กลุ่มมักสั่งคนละอย่าง ถ้ามีแต่ชาไทยจะเสียยอดครึ่งหนึ่งของทุกกลุ่ม · รอบ 7: เบสชาเขียวไม่มีน้ำตาลแล้ว จึงเติมน้ำเชื่อม 1:1 ชดเชย = 0.128 × ปริมาณเบสชาเขียว
A119: =IF($B119="","",$B119&"|"&$C119&"|"&$D119) -> Green Tea|22 oz|50% | B119: Green Tea | C119: 22 oz | D119: 50% | E119: 0 | F119: 185.5 | G119: 0 | H119: 60.5 | I119: 22 | J119: =ROUND(0+$AD$2*F119,1) -> 23.7 | K119: 0 | L119: 0 | M119: 0 | N119: 0 | O119: 0 | P119: 0 | Q119: 0 | R119: 0 | S119: 330 | T119: 0 | U119: 0 | V119: =E119+F119+G119+H119+I119+J119+K119+M119+N119+P119+Q119+T119+U119 -> 291.7 | W119: =ROUND(E119*ต้นทุนและราคา!$C$4+F119*ต้นทุนและราคา!$C$5+G119*ต้นทุนและราคา!$C$6+H119*ต้นทุนและราคา!$C$7+I119*ต้นทุนและราคา!$C$8+J119*ต้นทุนและราคา!$C$9+K119*ต้นทุนและราคา!$C$10+L119*ต้นทุนและราคา!$C$11+M119*ต้นทุนและราคา!$C$12+N119*ต้นทุนและราคา!$C$13+O119*ต้นทุนและราคา!$C$14+P119*ต้นทุนและราคา!$C$15+Q119*ต้นทุนและราคา!$C$16+R119*ต้นทุนและราคา!$C$17+S119*ต้นทุนและราคา!$C$18+T119*ต้นทุนและราคา!$C$19+U119*ต้นทุนและราคา!$C$20+IF($C119="16 oz",ต้นทุนและราคา!$C$21,IF($C119="20 oz",ต้นทุนและราคา!$C$22,ต้นทุนและราคา!$C$23)),2) -> 20.34 | X119: {=IFERROR(INDEX(ต้นทุนและราคา!$C$26:$E$101,MATCH($B119,ต้นทุนและราคา!$A$26:$A$101,0),IF($C119="16 oz",1,IF($C119="20 oz",2,3))),"")} -> 55 | Y119: =IFERROR(($X119-$W119)/$X119,"") -> 0.63018182 | Z119: เมนูใหม่ — เปิดไลน์ชาเขียว: ลูกค้ามาเป็นคู่/กลุ่มมักสั่งคนละอย่าง ถ้ามีแต่ชาไทยจะเสียยอดครึ่งหนึ่งของทุกกลุ่ม · รอบ 7: เบสชาเขียวไม่มีน้ำตาลแล้ว จึงเติมน้ำเชื่อม 1:1 ชดเชย = 0.128 × ปริมาณเบสชาเขียว
A120: =IF($B120="","",$B120&"|"&$C120&"|"&$D120) -> Green Tea|22 oz|75% | B120: Green Tea | C120: 22 oz | D120: 75% | E120: 0 | F120: 185.5 | G120: 0 | H120: 52 | I120: 33 | J120: =ROUND(0+$AD$2*F120,1) -> 23.7 | K120: 0 | L120: 0 | M120: 0 | N120: 0 | O120: 0 | P120: 0 | Q120: 0 | R120: 0 | S120: 330 | T120: 0 | U120: 0 | V120: =E120+F120+G120+H120+I120+J120+K120+M120+N120+P120+Q120+T120+U120 -> 294.2 | W120: =ROUND(E120*ต้นทุนและราคา!$C$4+F120*ต้นทุนและราคา!$C$5+G120*ต้นทุนและราคา!$C$6+H120*ต้นทุนและราคา!$C$7+I120*ต้นทุนและราคา!$C$8+J120*ต้นทุนและราคา!$C$9+K120*ต้นทุนและราคา!$C$10+L120*ต้นทุนและราคา!$C$11+M120*ต้นทุนและราคา!$C$12+N120*ต้นทุนและราคา!$C$13+O120*ต้นทุนและราคา!$C$14+P120*ต้นทุนและราคา!$C$15+Q120*ต้นทุนและราคา!$C$16+R120*ต้นทุนและราคา!$C$17+S120*ต้นทุนและราคา!$C$18+T120*ต้นทุนและราคา!$C$19+U120*ต้นทุนและราคา!$C$20+IF($C120="16 oz",ต้นทุนและราคา!$C$21,IF($C120="20 oz",ต้นทุนและราคา!$C$22,ต้นทุนและราคา!$C$23)),2) -> 20.47 | X120: {=IFERROR(INDEX(ต้นทุนและราคา!$C$26:$E$101,MATCH($B120,ต้นทุนและราคา!$A$26:$A$101,0),IF($C120="16 oz",1,IF($C120="20 oz",2,3))),"")} -> 55 | Y120: =IFERROR(($X120-$W120)/$X120,"") -> 0.62781818 | Z120: เมนูใหม่ — เปิดไลน์ชาเขียว: ลูกค้ามาเป็นคู่/กลุ่มมักสั่งคนละอย่าง ถ้ามีแต่ชาไทยจะเสียยอดครึ่งหนึ่งของทุกกลุ่ม · รอบ 7: เบสชาเขียวไม่มีน้ำตาลแล้ว จึงเติมน้ำเชื่อม 1:1 ชดเชย = 0.128 × ปริมาณเบสชาเขียว
